Workbook

Sheet 01_INPUTS
A1: 01_INPUTS — Única interfaz de carga manual: Identificación, Condiciones de Ronda y Decisiones D1–D8
A2: Azul = celda editable (decisión CADIZ o condición de ronda publicada por CESIM). Negro = fórmula de arrastre (edítese solo si CESIM publica un valor nuevo). Gris = dato histórico real (Ronda 0/1, no editar). Para agregar una ronda nueva: completar la columna de esa ronda; el resto de las hojas ya está preparado hasta la Ronda 12. | U2: PESIMISTA
U3: OPTIMISTA
A4: Bloque | B4: Variable | C4: Dimensión | D4: Unidad | E4: Tipo | F4: Fuente | G4: Ronda 0 | H4: Ronda 1 | I4: Ronda 2 | J4: Ronda 3 | K4: Ronda 4 | L4: Ronda 5 | M4: Ronda 6 | N4: Ronda 7 | O4: Ronda 8 | P4: Ronda 9 | Q4: Ronda 10 | R4: Ronda 11 | S4: Ronda 12 | U4: BASE
A5: SECCIÓN [SUPUESTO PROPIO] · MATRIZ DE SENSIBILIDAD (planificación propia, NO es una regla CESIM — no afecta Ronda 2 con Escenario Activo=BASE)
A6: Pesimista/Optimista en C/D → (Base fija en 0%, col. E oculta a propósito) | C6: Pesimista | D6: Optimista | E6: Base (fija, oculta) | U6: Equilibrado
A7: SENS · Supuesto propio | B7: Desvío en Crecimiento de Mercado (vs. condición publicada) | C7: -0.03 | D7: 0.03 | E7: 0 | F7: CESIM R2 | U7: Precio bajo
A8: SENS · Supuesto propio | B8: Agresividad de la Competencia (recorte a la cuota efectiva de CADIZ) | C8: 0.05 | D8: 0 | E8: 0 | F8: CESIM R2 | U8: Características
A9: SENS · Supuesto propio | B9: Escenario Activo | C9: BASE | D9: texto | E9: DECISIÓN CADIZ (planificación) | F9: Ver comentario | U9: Sostenibilidad
A10: SENS · Supuesto propio | B10: Factor de Crecimiento Activo (calculado) | C10: =INDEX(C7:E7,MATCH(01_INPUTS!$C$9,$U$2:$U$4,0)) -> 0 | D10: % | E10: CÁLCULO | F10: Ver comentario | U10: Marca
A11: SENS · Supuesto propio | B11: Factor de Competencia Activo (calculado) | C11: =INDEX(C8:E8,MATCH(01_INPUTS!$C$9,$U$2:$U$4,0)) -> 0 | D11: % | E11: CÁLCULO | F11: Ver comentario
U12: 1
A13: SECCIÓN A · IDENTIFICACIÓN | U13: 2
A14: A. Identificación | B14: Número de ronda | C14: - | D14: n° | E14: CÁLCULO | G14: 0 | H14: 1 | I14: 2 | J14: 3 | K14: 4 | L14: 5 | M14: 6 | N14: 7 | O14: 8 | P14: 9 | Q14: 10 | R14: 11 | S14: 12 | U14: 3
A15: A. Identificación | B15: Escenario | C15: - | D15: texto | E15: DECISIÓN CADIZ | F15: Ver comentario | G15: n/a (histórico) | H15: n/a (histórico) | I15: A
A16: A. Identificación | B16: Estado | C16: - | D16: REAL/PLAN/SIM | E16: DECISIÓN CADIZ | F16: CESIM R2 | G16: REAL | H16: REAL | I16: PLAN | J16: PLAN
A17: A. Identificación | B17: RONDA_ACTIVA (calculado) | C17: - | D17: VERDADERO/FALSO | E17: CÁLCULO | F17: Ver comentario | G17: =TRUE() -> TRUE | H17: =TRUE() -> TRUE | I17: =AND(OR(I16="PLAN",I16="SIM",I16="REAL"),ISNUMBER(I110)) -> TRUE | J17: =AND(OR(J16="PLAN",J16="SIM",J16="REAL"),ISNUMBER(J110)) -> FALSE | K17: =AND(OR(K16="PLAN",K16="SIM",K16="REAL"),ISNUMBER(K110)) -> FALSE | L17: =AND(OR(L16="PLAN",L16="SIM",L16="REAL"),ISNUMBER(L110)) -> FALSE | M17: =AND(OR(M16="PLAN",M16="SIM",M16="REAL"),ISNUMBER(M110)) -> FALSE | N17: =AND(OR(N16="PLAN",N16="SIM",N16="REAL"),ISNUMBER(N110)) -> FALSE | O17: =AND(OR(O16="PLAN",O16="SIM",O16="REAL"),ISNUMBER(O110)) -> FALSE | P17: =AND(OR(P16="PLAN",P16="SIM",P16="REAL"),ISNUMBER(P110)) -> FALSE | ... S17: =AND(OR(S16="PLAN",S16="SIM",S16="REAL"),ISNUMBER(S110)) -> FALSE
A19: SECCIÓN B · CONDICIONES DE RONDA (valores publicados por CESIM en 'Condiciones' de cada ronda — R3-R12 arrastran el último valor conocido, EDITABLE en cuanto se publique el real)
A20: B. Condiciones | B20: Crecimiento de mercado esperado (vs. ronda anterior) | C20: EE.UU. | D20: % | E20: CONDICIÓN DE RONDA | F20: CESIM R2 | G20: n/a (Ronda 0, sin ronda anterior) | H20: n/a (no cargado retroactivamente) | I20: 0.05 | J20: =I20 -> 0.05 | K20: =J20 -> 0.05 | L20: =K20 -> 0.05 | M20: =L20 -> 0.05 | N20: =M20 -> 0.05 | O20: =N20 -> 0.05 | P20: =O20 -> 0.05 | Q20: =P20 -> 0.05 | ... S20: =R20 -> 0.05
A21: B. Condiciones | B21: Crecimiento de mercado esperado (vs. ronda anterior) | C21: China | D21: % | E21: CONDICIÓN DE RONDA | F21: CESIM R2 | G21: n/a (Ronda 0, sin ronda anterior) | H21: n/a (no cargado retroactivamente) | I21: 0.085 | J21: =I21 -> 0.085 | K21: =J21 -> 0.085 | L21: =K21 -> 0.085 | M21: =L21 -> 0.085 | N21: =M21 -> 0.085 | O21: =N21 -> 0.085 | P21: =O21 -> 0.085 | Q21: =P21 -> 0.085 | ... S21: =R21 -> 0.085
A22: B. Condiciones | B22: Crecimiento de mercado esperado (vs. ronda anterior) | C22: Europa | D22: % | E22: CONDICIÓN DE RONDA | F22: CESIM R2 | G22: n/a (Ronda 0, sin ronda anterior) | H22: n/a (no cargado retroactivamente) | I22: 0.03 | J22: =I22 -> 0.03 | K22: =J22 -> 0.03 | L22: =K22 -> 0.03 | M22: =L22 -> 0.03 | N22: =M22 -> 0.03 | O22: =N22 -> 0.03 | P22: =O22 -> 0.03 | Q22: =P22 -> 0.03 | ... S22: =R22 -> 0.03
A23: B. Condiciones | B23: Tasa de impuesto corporativo | C23: EE.UU. | D23: % | E23: CONDICIÓN DE RONDA | F23: CESIM R2 | G23: 0.22 | H23: 0.25 | I23: 0.22 | J23: =I23 -> 0.22 | K23: =J23 -> 0.22 | L23: =K23 -> 0.22 | M23: =L23 -> 0.22 | N23: =M23 -> 0.22 | O23: =N23 -> 0.22 | P23: =O23 -> 0.22 | Q23: =P23 -> 0.22 | ... S23: =R23 -> 0.22
A24: B. Condiciones | B24: Tasa de impuesto corporativo | C24: China | D24: % | E24: CONDICIÓN DE RONDA | F24: CESIM R2 | G24: 0.25 | H24: 0.28 | I24: 0.25 | J24: =I24 -> 0.25 | K24: =J24 -> 0.25 | L24: =K24 -> 0.25 | M24: =L24 -> 0.25 | N24: =M24 -> 0.25 | O24: =N24 -> 0.25 | P24: =O24 -> 0.25 | Q24: =P24 -> 0.25 | ... S24: =R24 -> 0.25
A25: B. Condiciones | B25: Tasa de impuesto corporativo | C25: Europa | D25: % | E25: CONDICIÓN DE RONDA | F25: CESIM R2 | G25: 0.21 | H25: 0.23 | I25: 0.21 | J25: =I25 -> 0.21 | K25: =J25 -> 0.21 | L25: =K25 -> 0.21 | M25: =L25 -> 0.21 | N25: =M25 -> 0.21 | O25: =N25 -> 0.21 | P25: =O25 -> 0.21 | Q25: =P25 -> 0.21 | ... S25: =R25 -> 0.21
A26: B. Condiciones | B26: Tipo de cambio (USD por 1 unidad de moneda local) | C26: China (RMB) | D26: USD/u.moneda | E26: CONDICIÓN DE RONDA | G26: n/a (Ronda 0) | H26: 0.162 | I26: 0.1507 | J26: =I26 -> 0.1507 | K26: =J26 -> 0.1507 | L26: =K26 -> 0.1507 | M26: =L26 -> 0.1507 | N26: =M26 -> 0.1507 | O26: =N26 -> 0.1507 | P26: =O26 -> 0.1507 | Q26: =P26 -> 0.1507 | ... S26: =R26 -> 0.1507
A27: B. Condiciones | B27: Tipo de cambio (USD por 1 unidad de moneda local) | C27: Europa (EUR) | D27: USD/u.moneda | E27: CONDICIÓN DE RONDA | G27: n/a (Ronda 0) | H27: 1.146 | I27: 1.1126 | J27: =I27 -> 1.1126 | K27: =J27 -> 1.1126 | L27: =K27 -> 1.1126 | M27: =L27 -> 1.1126 | N27: =M27 -> 1.1126 | O27: =N27 -> 1.1126 | P27: =O27 -> 1.1126 | Q27: =P27 -> 1.1126 | ... S27: =R27 -> 1.1126
A28: B. Condiciones | B28: Efectivo mínimo de fin de ronda | C28: Todos los países (por país) | D28: USD | E28: CONDICIÓN DE RONDA | F28: Supuesto propio | G28: n/a (Ronda 0) | H28: 2000000 | I28: 2000000 | J28: =I28 -> 2000000 | K28: =J28 -> 2000000 | L28: =K28 -> 2000000 | M28: =L28 -> 2000000 | N28: =M28 -> 2000000 | O28: =N28 -> 2000000 | P28: =O28 -> 2000000 | Q28: =P28 -> 2000000 | ... S28: =R28 -> 2000000
A29: B. Condiciones | B29: Tasa de interés — deuda a largo plazo | C29: Casa matriz EE.UU. | D29: %/ronda | E29: CONDICIÓN DE RONDA | G29: n/a (Ronda 0) | H29: 0.08 | I29: 0.05 | J29: =I29 -> 0.05 | K29: =J29 -> 0.05 | L29: =K29 -> 0.05 | M29: =L29 -> 0.05 | N29: =M29 -> 0.05 | O29: =N29 -> 0.05 | P29: =O29 -> 0.05 | Q29: =P29 -> 0.05 | ... S29: =R29 -> 0.05
A30: B. Condiciones | B30: Tasa de interés — deuda a corto plazo | C30: EE.UU. | D30: %/ronda | E30: CONDICIÓN DE RONDA | G30: n/a (Ronda 0) | H30: 0.15 | I30: 0.1 | J30: =I30 -> 0.1 | K30: =J30 -> 0.1 | L30: =K30 -> 0.1 | M30: =L30 -> 0.1 | N30: =M30 -> 0.1 | O30: =N30 -> 0.1 | P30: =O30 -> 0.1 | Q30: =P30 -> 0.1 | ... S30: =R30 -> 0.1
A31: B. Condiciones | B31: Tasa de interés — deuda a corto plazo | C31: China | D31: %/ronda | E31: CONDICIÓN DE RONDA | G31: n/a (Ronda 0) | H31: 0.1 | I31: 0.07 | J31: =I31 -> 0.07 | K31: =J31 -> 0.07 | L31: =K31 -> 0.07 | M31: =L31 -> 0.07 | N31: =M31 -> 0.07 | O31: =N31 -> 0.07 | P31: =O31 -> 0.07 | Q31: =P31 -> 0.07 | ... S31: =R31 -> 0.07
A32: B. Condiciones | B32: Tasa de interés — deuda a corto plazo | C32: Europa | D32: %/ronda | E32: CONDICIÓN DE RONDA | G32: n/a (Ronda 0) | H32: 0.085 | I32: 0.055 | J32: =I32 -> 0.055 | K32: =J32 -> 0.055 | L32: =K32 -> 0.055 | M32: =L32 -> 0.055 | N32: =M32 -> 0.055 | O32: =N32 -> 0.055 | P32: =O32 -> 0.055 | Q32: =P32 -> 0.055 | ... S32: =R32 -> 0.055
A33: B. Condiciones | B33: Tasa de interés sobre efectivo | C33: EE.UU. | D33: %/ronda | E33: CONDICIÓN DE RONDA | G33: n/a (Ronda 0) | H33: 0.06 | I33: 0.04 | J33: =I33 -> 0.04 | K33: =J33 -> 0.04 | L33: =K33 -> 0.04 | M33: =L33 -> 0.04 | N33: =M33 -> 0.04 | O33: =N33 -> 0.04 | P33: =O33 -> 0.04 | Q33: =P33 -> 0.04 | ... S33: =R33 -> 0.04
A34: B. Condiciones | B34: Tasa de interés sobre efectivo | C34: China | D34: %/ronda | E34: CONDICIÓN DE RONDA | G34: n/a (Ronda 0) | H34: 0.065 | I34: 0.055 | J34: =I34 -> 0.055 | K34: =J34 -> 0.055 | L34: =K34 -> 0.055 | M34: =L34 -> 0.055 | N34: =M34 -> 0.055 | O34: =N34 -> 0.055 | P34: =O34 -> 0.055 | Q34: =P34 -> 0.055 | ... S34: =R34 -> 0.055
A35: B. Condiciones | B35: Tasa de interés sobre efectivo | C35: Europa | D35: %/ronda | E35: CONDICIÓN DE RONDA | G35: n/a (Ronda 0) | H35: 0.055 | I35: 0.03 | J35: =I35 -> 0.03 | K35: =J35 -> 0.03 | L35: =K35 -> 0.03 | M35: =L35 -> 0.03 | N35: =M35 -> 0.03 | O35: =N35 -> 0.03 | P35: =O35 -> 0.03 | Q35: =P35 -> 0.03 | ... S35: =R35 -> 0.03
A36: B. Condiciones | B36: Costo de la característica | C36: EE.UU. | D36: USD/u. | E36: CONDICIÓN DE RONDA | F36: RDOS R1 | G36: n/a (Ronda 0) | H36: 700 | I36: 700 | J36: =I36 -> 700 | K36: =J36 -> 700 | L36: =K36 -> 700 | M36: =L36 -> 700 | N36: =M36 -> 700 | O36: =N36 -> 700 | P36: =O36 -> 700 | Q36: =P36 -> 700 | ... S36: =R36 -> 700
A37: B. Condiciones | B37: Costo de la característica | C37: China | D37: USD/u. | E37: CONDICIÓN DE RONDA | F37: RDOS R1 | G37: n/a (Ronda 0) | H37: 650 | I37: 650 | J37: =I37 -> 650 | K37: =J37 -> 650 | L37: =K37 -> 650 | M37: =L37 -> 650 | N37: =M37 -> 650 | O37: =N37 -> 650 | P37: =O37 -> 650 | Q37: =P37 -> 650 | ... S37: =R37 -> 650
A38: B. Condiciones | B38: Costo de la característica | C38: Europa | D38: USD/u. | E38: CONDICIÓN DE RONDA | F38: RDOS R1 | G38: n/a (Ronda 0) | H38: 750 | I38: 750 | J38: =I38 -> 750 | K38: =J38 -> 750 | L38: =K38 -> 750 | M38: =L38 -> 750 | N38: =M38 -> 750 | O38: =N38 -> 750 | P38: =O38 -> 750 | Q38: =P38 -> 750 | ... S38: =R38 -> 750
A39: B. Condiciones | B39: Costo de adquirir tecnología nueva | C39: Combustión | D39: USD | E39: CONDICIÓN DE RONDA | F39: CESIM R2 | G39: n/a (ya habilitada para CADIZ) | H39: n/a (ya habilitada para CADIZ) | I39: n/a (ya habilitada para CADIZ) | J39: n/a (ya habilitada para CADIZ) | K39: n/a (ya habilitada para CADIZ) | L39: n/a (ya habilitada para CADIZ) | M39: n/a (ya habilitada para CADIZ) | N39: n/a (ya habilitada para CADIZ) | O39: n/a (ya habilitada para CADIZ) | P39: n/a (ya habilitada para CADIZ) | Q39: n/a (ya habilitada para CADIZ) | R39: n/a (ya habilitada para CADIZ) | S39: n/a (ya habilitada para CADIZ)
A40: B. Condiciones | B40: Costo de adquirir tecnología nueva | C40: Híbrido | D40: USD | E40: CONDICIÓN DE RONDA | F40: CESIM R2 | G40: n/a (ya habilitada para CADIZ) | H40: n/a (ya habilitada para CADIZ) | I40: n/a (ya habilitada para CADIZ) | J40: n/a (ya habilitada para CADIZ) | K40: n/a (ya habilitada para CADIZ) | L40: n/a (ya habilitada para CADIZ) | M40: n/a (ya habilitada para CADIZ) | N40: n/a (ya habilitada para CADIZ) | O40: n/a (ya habilitada para CADIZ) | P40: n/a (ya habilitada para CADIZ) | Q40: n/a (ya habilitada para CADIZ) | R40: n/a (ya habilitada para CADIZ) | S40: n/a (ya habilitada para CADIZ)
A41: B. Condiciones | B41: Costo de adquirir tecnología nueva | C41: Eléctrico | D41: USD | E41: CONDICIÓN DE RONDA | F41: CESIM R2 | G41: n/a (no verificado) | H41: n/a (no verificado) | J41: =I41 -> 0 | K41: =J41 -> 0 | L41: =K41 -> 0 | M41: =L41 -> 0 | N41: =M41 -> 0 | O41: =N41 -> 0 | P41: =O41 -> 0 | Q41: =P41 -> 0 | ... S41: =R41 -> 0
...

Sheet 02_ESTADOS_PROYECTADOS
A1: 02_ESTADOS_PROYECTADOS — Estados financieros con selector GLOBAL/EE.UU./CHINA/EUROPA (B2) y detalle por país agrupado ([+]/[-] a la izquierda) | U1: GLOBAL
A2: SELECTOR DE VISTA (celda B2) → | B2: GLOBAL | C2: GLOBAL = consolidado (Σ 3 países, con eliminaciones). EE.UU./CHINA/EUROPA = ese país únicamente. VISTA DESPLEGADA = igual a GLOBAL en la fila principal (pensada para cuando se quiere ver todo el detalle por país expandido de entrada). El detalle por país de cada línea está SIEMPRE presente debajo, agrupado con el outline nativo de Excel/LibreOffice -- usar [+]/[-] a la izquierda de la grilla para expandir/colapsar, independientemente de lo que diga B2. | U2: EE.UU.
A3: Detalle por país: Ingresos = 'Ingresos de mercados' (externo, sin transferencias internas). Costos = Costos y gastos totales EXCLUYENDO costos de productos importados (misma base de eliminación que GLOBAL). El resto de las líneas suma exacto a GLOBAL. Celdas en VERDE = link, no editar aquí. | U3: CHINA
U4: EUROPA
A5: Concepto | B5: Unidad | G5: R0 | H5: R1 | I5: R2 | J5: R3 | K5: R4 | L5: R5 | M5: R6 | N5: R7 | O5: R8 | P5: R9 | Q5: R10 | R5: R11 | S5: R12 | U5: VISTA DESPLEGADA
A6: ESTADO DE RESULTADOS
A7: Ingresos por ventas | B7: USD | G7: =CHOOSE(MATCH($B$2,$U$1:$U$5,0),_ENGINE_FINANCIERO!G160,_ENGINE_FINANCIERO!G5,_ENGINE_FINANCIERO!G52,_ENGINE_FINANCIERO!G99,_ENGINE_FINANCIERO!G160) -> 39489000000 | H7: =CHOOSE(MATCH($B$2,$U$1:$U$5,0),_ENGINE_FINANCIERO!H160,_ENGINE_FINANCIERO!H5,_ENGINE_FINANCIERO!H52,_ENGINE_FINANCIERO!H99,_ENGINE_FINANCIERO!H160) -> n/a (RDOS R1 Global no desagregado aquí) | I7: =IF(01_INPUTS!I17,CHOOSE(MATCH($B$2,$U$1:$U$5,0),_ENGINE_FINANCIERO!I160,_ENGINE_FINANCIERO!I5,_ENGINE_FINANCIERO!I52,_ENGINE_FINANCIERO!I99,_ENGINE_FINANCIERO!I160),"") -> 7.6940913e+10 | J7: =IF(01_INPUTS!J17,CHOOSE(MATCH($B$2,$U$1:$U$5,0),_ENGINE_FINANCIERO!J160,_ENGINE_FINANCIERO!J5,_ENGINE_FINANCIERO!J52,_ENGINE_FINANCIERO!J99,_ENGINE_FINANCIERO!J160),"") | K7: =IF(01_INPUTS!K17,CHOOSE(MATCH($B$2,$U$1:$U$5,0),_ENGINE_FINANCIERO!K160,_ENGINE_FINANCIERO!K5,_ENGINE_FINANCIERO!K52,_ENGINE_FINANCIERO!K99,_ENGINE_FINANCIERO!K160),"") | L7: =IF(01_INPUTS!L17,CHOOSE(MATCH($B$2,$U$1:$U$5,0),_ENGINE_FINANCIERO!L160,_ENGINE_FINANCIERO!L5,_ENGINE_FINANCIERO!L52,_ENGINE_FINANCIERO!L99,_ENGINE_FINANCIERO!L160),"") | M7: =IF(01_INPUTS!M17,CHOOSE(MATCH($B$2,$U$1:$U$5,0),_ENGINE_FINANCIERO!M160,_ENGINE_FINANCIERO!M5,_ENGINE_FINANCIERO!M52,_ENGINE_FINANCIERO!M99,_ENGINE_FINANCIERO!M160),"") | N7: =IF(01_INPUTS!N17,CHOOSE(MATCH($B$2,$U$1:$U$5,0),_ENGINE_FINANCIERO!N160,_ENGINE_FINANCIERO!N5,_ENGINE_FINANCIERO!N52,_ENGINE_FINANCIERO!N99,_ENGINE_FINANCIERO!N160),"") | O7: =IF(01_INPUTS!O17,CHOOSE(MATCH($B$2,$U$1:$U$5,0),_ENGINE_FINANCIERO!O160,_ENGINE_FINANCIERO!O5,_ENGINE_FINANCIERO!O52,_ENGINE_FINANCIERO!O99,_ENGINE_FINANCIERO!O160),"") | P7: =IF(01_INPUTS!P17,CHOOSE(MATCH($B$2,$U$1:$U$5,0),_ENGINE_FINANCIERO!P160,_ENGINE_FINANCIERO!P5,_ENGINE_FINANCIERO!P52,_ENGINE_FINANCIERO!P99,_ENGINE_FINANCIERO!P160),"") | ... S7: =IF(01_INPUTS!S17,CHOOSE(MATCH($B$2,$U$1:$U$5,0),_ENGINE_FINANCIERO!S160,_ENGINE_FINANCIERO!S5,_ENGINE_FINANCIERO!S52,_ENGINE_FINANCIERO!S99,_ENGINE_FINANCIERO!S160),"")
A8: EE.UU. | B8: USD | G8: =_ENGINE_FINANCIERO!G5 -> 0 | H8: =_ENGINE_FINANCIERO!H5 -> 0 | I8: =IF(01_INPUTS!I17,_ENGINE_FINANCIERO!I5,"") -> 2.5052171e+10 | J8: =IF(01_INPUTS!J17,_ENGINE_FINANCIERO!J5,"") | K8: =IF(01_INPUTS!K17,_ENGINE_FINANCIERO!K5,"") | L8: =IF(01_INPUTS!L17,_ENGINE_FINANCIERO!L5,"") | M8: =IF(01_INPUTS!M17,_ENGINE_FINANCIERO!M5,"") | N8: =IF(01_INPUTS!N17,_ENGINE_FINANCIERO!N5,"") | O8: =IF(01_INPUTS!O17,_ENGINE_FINANCIERO!O5,"") | P8: =IF(01_INPUTS!P17,_ENGINE_FINANCIERO!P5,"") | ... S8: =IF(01_INPUTS!S17,_ENGINE_FINANCIERO!S5,"")
A9: China | B9: USD | G9: =_ENGINE_FINANCIERO!G52 -> 0 | H9: =_ENGINE_FINANCIERO!H52 -> 0 | I9: =IF(01_INPUTS!I17,_ENGINE_FINANCIERO!I52,"") -> 2.0223492e+10 | J9: =IF(01_INPUTS!J17,_ENGINE_FINANCIERO!J52,"") | K9: =IF(01_INPUTS!K17,_ENGINE_FINANCIERO!K52,"") | L9: =IF(01_INPUTS!L17,_ENGINE_FINANCIERO!L52,"") | M9: =IF(01_INPUTS!M17,_ENGINE_FINANCIERO!M52,"") | N9: =IF(01_INPUTS!N17,_ENGINE_FINANCIERO!N52,"") | O9: =IF(01_INPUTS!O17,_ENGINE_FINANCIERO!O52,"") | P9: =IF(01_INPUTS!P17,_ENGINE_FINANCIERO!P52,"") | ... S9: =IF(01_INPUTS!S17,_ENGINE_FINANCIERO!S52,"")
A10: Europa | B10: USD | G10: =_ENGINE_FINANCIERO!G99 -> 0 | H10: =_ENGINE_FINANCIERO!H99 -> 0 | I10: =IF(01_INPUTS!I17,_ENGINE_FINANCIERO!I99,"") -> 3.166525e+10 | J10: =IF(01_INPUTS!J17,_ENGINE_FINANCIERO!J99,"") | K10: =IF(01_INPUTS!K17,_ENGINE_FINANCIERO!K99,"") | L10: =IF(01_INPUTS!L17,_ENGINE_FINANCIERO!L99,"") | M10: =IF(01_INPUTS!M17,_ENGINE_FINANCIERO!M99,"") | N10: =IF(01_INPUTS!N17,_ENGINE_FINANCIERO!N99,"") | O10: =IF(01_INPUTS!O17,_ENGINE_FINANCIERO!O99,"") | P10: =IF(01_INPUTS!P17,_ENGINE_FINANCIERO!P99,"") | ... S10: =IF(01_INPUTS!S17,_ENGINE_FINANCIERO!S99,"")
A11: Costos y gastos totales | B11: USD | G11: =CHOOSE(MATCH($B$2,$U$1:$U$5,0),_ENGINE_FINANCIERO!G161,(_ENGINE_FINANCIERO!G18-_ENGINE_FINANCIERO!G9),(_ENGINE_FINANCIERO!G65-_ENGINE_FINANCIERO!G56),(_ENGINE_FINANCIERO!G112-_ENGINE_FINANCIERO!G103),_ENGINE_FINANCIERO!G161) -> 3.5337849e+10 | H11: =CHOOSE(MATCH($B$2,$U$1:$U$5,0),_ENGINE_FINANCIERO!H161,(_ENGINE_FINANCIERO!H18-_ENGINE_FINANCIERO!H9),(_ENGINE_FINANCIERO!H65-_ENGINE_FINANCIERO!H56),(_ENGINE_FINANCIERO!H112-_ENGINE_FINANCIERO!H103),_ENGINE_FINANCIERO!H161) -> n/a | I11: =IF(01_INPUTS!I17,CHOOSE(MATCH($B$2,$U$1:$U$5,0),_ENGINE_FINANCIERO!I161,(_ENGINE_FINANCIERO!I18-_ENGINE_FINANCIERO!I9),(_ENGINE_FINANCIERO!I65-_ENGINE_FINANCIERO!I56),(_ENGINE_FINANCIERO!I112-_ENGINE_FINANCIERO!I103),_ENGINE_FINANCIERO!I161),"") -> 5.8142483e+10 | J11: =IF(01_INPUTS!J17,CHOOSE(MATCH($B$2,$U$1:$U$5,0),_ENGINE_FINANCIERO!J161,(_ENGINE_FINANCIERO!J18-_ENGINE_FINANCIERO!J9),(_ENGINE_FINANCIERO!J65-_ENGINE_FINANCIERO!J56),(_ENGINE_FINANCIERO!J112-_ENGINE_FINANCIERO!J103),_ENGINE_FINANCIERO!J161),"") | K11: =IF(01_INPUTS!K17,CHOOSE(MATCH($B$2,$U$1:$U$5,0),_ENGINE_FINANCIERO!K161,(_ENGINE_FINANCIERO!K18-_ENGINE_FINANCIERO!K9),(_ENGINE_FINANCIERO!K65-_ENGINE_FINANCIERO!K56),(_ENGINE_FINANCIERO!K112-_ENGINE_FINANCIERO!K103),_ENGINE_FINANCIERO!K161),"") | L11: =IF(01_INPUTS!L17,CHOOSE(MATCH($B$2,$U$1:$U$5,0),_ENGINE_FINANCIERO!L161,(_ENGINE_FINANCIERO!L18-_ENGINE_FINANCIERO!L9),(_ENGINE_FINANCIERO!L65-_ENGINE_FINANCIERO!L56),(_ENGINE_FINANCIERO!L112-_ENGINE_FINANCIERO!L103),_ENGINE_FINANCIERO!L161),"") | M11: =IF(01_INPUTS!M17,CHOOSE(MATCH($B$2,$U$1:$U$5,0),_ENGINE_FINANCIERO!M161,(_ENGINE_FINANCIERO!M18-_ENGINE_FINANCIERO!M9),(_ENGINE_FINANCIERO!M65-_ENGINE_FINANCIERO!M56),(_ENGINE_FINANCIERO!M112-_ENGINE_FINANCIERO!M103),_ENGINE_FINANCIERO!M161),"") | N11: =IF(01_INPUTS!N17,CHOOSE(MATCH($B$2,$U$1:$U$5,0),_ENGINE_FINANCIERO!N161,(_ENGINE_FINANCIERO!N18-_ENGINE_FINANCIERO!N9),(_ENGINE_FINANCIERO!N65-_ENGINE_FINANCIERO!N56),(_ENGINE_FINANCIERO!N112-_ENGINE_FINANCIERO!N103),_ENGINE_FINANCIERO!N161),"") | O11: =IF(01_INPUTS!O17,CHOOSE(MATCH($B$2,$U$1:$U$5,0),_ENGINE_FINANCIERO!O161,(_ENGINE_FINANCIERO!O18-_ENGINE_FINANCIERO!O9),(_ENGINE_FINANCIERO!O65-_ENGINE_FINANCIERO!O56),(_ENGINE_FINANCIERO!O112-_ENGINE_FINANCIERO!O103),_ENGINE_FINANCIERO!O161),"") | P11: =IF(01_INPUTS!P17,CHOOSE(MATCH($B$2,$U$1:$U$5,0),_ENGINE_FINANCIERO!P161,(_ENGINE_FINANCIERO!P18-_ENGINE_FINANCIERO!P9),(_ENGINE_FINANCIERO!P65-_ENGINE_FINANCIERO!P56),(_ENGINE_FINANCIERO!P112-_ENGINE_FINANCIERO!P103),_ENGINE_FINANCIERO!P161),"") | ... S11: =IF(01_INPUTS!S17,CHOOSE(MATCH($B$2,$U$1:$U$5,0),_ENGINE_FINANCIERO!S161,(_ENGINE_FINANCIERO!S18-_ENGINE_FINANCIERO!S9),(_ENGINE_FINANCIERO!S65-_ENGINE_FINANCIERO!S56),(_ENGINE_FINANCIERO!S112-_ENGINE_FINANCIERO!S103),_ENGINE_FINANCIERO!S161),"")
A12: EE.UU. | B12: USD | G12: =(_ENGINE_FINANCIERO!G18-_ENGINE_FINANCIERO!G9) -> 0 | H12: =(_ENGINE_FINANCIERO!H18-_ENGINE_FINANCIERO!H9) -> 63000000 | I12: =IF(01_INPUTS!I17,(_ENGINE_FINANCIERO!I18-_ENGINE_FINANCIERO!I9),"") -> 2.7232405e+10 | J12: =IF(01_INPUTS!J17,(_ENGINE_FINANCIERO!J18-_ENGINE_FINANCIERO!J9),"") | K12: =IF(01_INPUTS!K17,(_ENGINE_FINANCIERO!K18-_ENGINE_FINANCIERO!K9),"") | L12: =IF(01_INPUTS!L17,(_ENGINE_FINANCIERO!L18-_ENGINE_FINANCIERO!L9),"") | M12: =IF(01_INPUTS!M17,(_ENGINE_FINANCIERO!M18-_ENGINE_FINANCIERO!M9),"") | N12: =IF(01_INPUTS!N17,(_ENGINE_FINANCIERO!N18-_ENGINE_FINANCIERO!N9),"") | O12: =IF(01_INPUTS!O17,(_ENGINE_FINANCIERO!O18-_ENGINE_FINANCIERO!O9),"") | P12: =IF(01_INPUTS!P17,(_ENGINE_FINANCIERO!P18-_ENGINE_FINANCIERO!P9),"") | ... S12: =IF(01_INPUTS!S17,(_ENGINE_FINANCIERO!S18-_ENGINE_FINANCIERO!S9),"")
A13: China | B13: USD | G13: =(_ENGINE_FINANCIERO!G65-_ENGINE_FINANCIERO!G56) -> 0 | H13: =(_ENGINE_FINANCIERO!H65-_ENGINE_FINANCIERO!H56) -> 95000000 | I13: =IF(01_INPUTS!I17,(_ENGINE_FINANCIERO!I65-_ENGINE_FINANCIERO!I56),"") -> 2.3565399e+10 | J13: =IF(01_INPUTS!J17,(_ENGINE_FINANCIERO!J65-_ENGINE_FINANCIERO!J56),"") | K13: =IF(01_INPUTS!K17,(_ENGINE_FINANCIERO!K65-_ENGINE_FINANCIERO!K56),"") | L13: =IF(01_INPUTS!L17,(_ENGINE_FINANCIERO!L65-_ENGINE_FINANCIERO!L56),"") | M13: =IF(01_INPUTS!M17,(_ENGINE_FINANCIERO!M65-_ENGINE_FINANCIERO!M56),"") | N13: =IF(01_INPUTS!N17,(_ENGINE_FINANCIERO!N65-_ENGINE_FINANCIERO!N56),"") | O13: =IF(01_INPUTS!O17,(_ENGINE_FINANCIERO!O65-_ENGINE_FINANCIERO!O56),"") | P13: =IF(01_INPUTS!P17,(_ENGINE_FINANCIERO!P65-_ENGINE_FINANCIERO!P56),"") | ... S13: =IF(01_INPUTS!S17,(_ENGINE_FINANCIERO!S65-_ENGINE_FINANCIERO!S56),"")
A14: Europa | B14: USD | G14: =(_ENGINE_FINANCIERO!G112-_ENGINE_FINANCIERO!G103) -> 0 | H14: =(_ENGINE_FINANCIERO!H112-_ENGINE_FINANCIERO!H103) -> 20000000 | I14: =IF(01_INPUTS!I17,(_ENGINE_FINANCIERO!I112-_ENGINE_FINANCIERO!I103),"") -> 7.344679e+09 | J14: =IF(01_INPUTS!J17,(_ENGINE_FINANCIERO!J112-_ENGINE_FINANCIERO!J103),"") | K14: =IF(01_INPUTS!K17,(_ENGINE_FINANCIERO!K112-_ENGINE_FINANCIERO!K103),"") | L14: =IF(01_INPUTS!L17,(_ENGINE_FINANCIERO!L112-_ENGINE_FINANCIERO!L103),"") | M14: =IF(01_INPUTS!M17,(_ENGINE_FINANCIERO!M112-_ENGINE_FINANCIERO!M103),"") | N14: =IF(01_INPUTS!N17,(_ENGINE_FINANCIERO!N112-_ENGINE_FINANCIERO!N103),"") | O14: =IF(01_INPUTS!O17,(_ENGINE_FINANCIERO!O112-_ENGINE_FINANCIERO!O103),"") | P14: =IF(01_INPUTS!P17,(_ENGINE_FINANCIERO!P112-_ENGINE_FINANCIERO!P103),"") | ... S14: =IF(01_INPUTS!S17,(_ENGINE_FINANCIERO!S112-_ENGINE_FINANCIERO!S103),"")
A15: EBITDA | B15: USD | G15: =CHOOSE(MATCH($B$2,$U$1:$U$5,0),_ENGINE_FINANCIERO!G162,_ENGINE_FINANCIERO!G19,_ENGINE_FINANCIERO!G66,_ENGINE_FINANCIERO!G113,_ENGINE_FINANCIERO!G162) -> 4.1511508e+09 | H15: =CHOOSE(MATCH($B$2,$U$1:$U$5,0),_ENGINE_FINANCIERO!H162,_ENGINE_FINANCIERO!H19,_ENGINE_FINANCIERO!H66,_ENGINE_FINANCIERO!H113,_ENGINE_FINANCIERO!H162) -> n/a | I15: =IF(01_INPUTS!I17,CHOOSE(MATCH($B$2,$U$1:$U$5,0),_ENGINE_FINANCIERO!I162,_ENGINE_FINANCIERO!I19,_ENGINE_FINANCIERO!I66,_ENGINE_FINANCIERO!I113,_ENGINE_FINANCIERO!I162),"") -> 1.879843e+10 | J15: =IF(01_INPUTS!J17,CHOOSE(MATCH($B$2,$U$1:$U$5,0),_ENGINE_FINANCIERO!J162,_ENGINE_FINANCIERO!J19,_ENGINE_FINANCIERO!J66,_ENGINE_FINANCIERO!J113,_ENGINE_FINANCIERO!J162),"") | K15: =IF(01_INPUTS!K17,CHOOSE(MATCH($B$2,$U$1:$U$5,0),_ENGINE_FINANCIERO!K162,_ENGINE_FINANCIERO!K19,_ENGINE_FINANCIERO!K66,_ENGINE_FINANCIERO!K113,_ENGINE_FINANCIERO!K162),"") | L15: =IF(01_INPUTS!L17,CHOOSE(MATCH($B$2,$U$1:$U$5,0),_ENGINE_FINANCIERO!L162,_ENGINE_FINANCIERO!L19,_ENGINE_FINANCIERO!L66,_ENGINE_FINANCIERO!L113,_ENGINE_FINANCIERO!L162),"") | M15: =IF(01_INPUTS!M17,CHOOSE(MATCH($B$2,$U$1:$U$5,0),_ENGINE_FINANCIERO!M162,_ENGINE_FINANCIERO!M19,_ENGINE_FINANCIERO!M66,_ENGINE_FINANCIERO!M113,_ENGINE_FINANCIERO!M162),"") | N15: =IF(01_INPUTS!N17,CHOOSE(MATCH($B$2,$U$1:$U$5,0),_ENGINE_FINANCIERO!N162,_ENGINE_FINANCIERO!N19,_ENGINE_FINANCIERO!N66,_ENGINE_FINANCIERO!N113,_ENGINE_FINANCIERO!N162),"") | O15: =IF(01_INPUTS!O17,CHOOSE(MATCH($B$2,$U$1:$U$5,0),_ENGINE_FINANCIERO!O162,_ENGINE_FINANCIERO!O19,_ENGINE_FINANCIERO!O66,_ENGINE_FINANCIERO!O113,_ENGINE_FINANCIERO!O162),"") | P15: =IF(01_INPUTS!P17,CHOOSE(MATCH($B$2,$U$1:$U$5,0),_ENGINE_FINANCIERO!P162,_ENGINE_FINANCIERO!P19,_ENGINE_FINANCIERO!P66,_ENGINE_FINANCIERO!P113,_ENGINE_FINANCIERO!P162),"") | ... S15: =IF(01_INPUTS!S17,CHOOSE(MATCH($B$2,$U$1:$U$5,0),_ENGINE_FINANCIERO!S162,_ENGINE_FINANCIERO!S19,_ENGINE_FINANCIERO!S66,_ENGINE_FINANCIERO!S113,_ENGINE_FINANCIERO!S162),"")
A16: EE.UU. | B16: USD | G16: =_ENGINE_FINANCIERO!G19 -> 0 | H16: =_ENGINE_FINANCIERO!H19 -> -63000000 | I16: =IF(01_INPUTS!I17,_ENGINE_FINANCIERO!I19,"") -> 4.0840869e+09 | J16: =IF(01_INPUTS!J17,_ENGINE_FINANCIERO!J19,"") | K16: =IF(01_INPUTS!K17,_ENGINE_FINANCIERO!K19,"") | L16: =IF(01_INPUTS!L17,_ENGINE_FINANCIERO!L19,"") | M16: =IF(01_INPUTS!M17,_ENGINE_FINANCIERO!M19,"") | N16: =IF(01_INPUTS!N17,_ENGINE_FINANCIERO!N19,"") | O16: =IF(01_INPUTS!O17,_ENGINE_FINANCIERO!O19,"") | P16: =IF(01_INPUTS!P17,_ENGINE_FINANCIERO!P19,"") | ... S16: =IF(01_INPUTS!S17,_ENGINE_FINANCIERO!S19,"")
A17: China | B17: USD | G17: =_ENGINE_FINANCIERO!G66 -> 0 | H17: =_ENGINE_FINANCIERO!H66 -> -95000000 | I17: =IF(01_INPUTS!I17,_ENGINE_FINANCIERO!I66,"") -> 3.5644927e+09 | J17: =IF(01_INPUTS!J17,_ENGINE_FINANCIERO!J66,"") | K17: =IF(01_INPUTS!K17,_ENGINE_FINANCIERO!K66,"") | L17: =IF(01_INPUTS!L17,_ENGINE_FINANCIERO!L66,"") | M17: =IF(01_INPUTS!M17,_ENGINE_FINANCIERO!M66,"") | N17: =IF(01_INPUTS!N17,_ENGINE_FINANCIERO!N66,"") | O17: =IF(01_INPUTS!O17,_ENGINE_FINANCIERO!O66,"") | P17: =IF(01_INPUTS!P17,_ENGINE_FINANCIERO!P66,"") | ... S17: =IF(01_INPUTS!S17,_ENGINE_FINANCIERO!S66,"")
A18: Europa | B18: USD | G18: =_ENGINE_FINANCIERO!G113 -> 0 | H18: =_ENGINE_FINANCIERO!H113 -> -20000000 | I18: =IF(01_INPUTS!I17,_ENGINE_FINANCIERO!I113,"") -> 1.114985e+10 | J18: =IF(01_INPUTS!J17,_ENGINE_FINANCIERO!J113,"") | K18: =IF(01_INPUTS!K17,_ENGINE_FINANCIERO!K113,"") | L18: =IF(01_INPUTS!L17,_ENGINE_FINANCIERO!L113,"") | M18: =IF(01_INPUTS!M17,_ENGINE_FINANCIERO!M113,"") | N18: =IF(01_INPUTS!N17,_ENGINE_FINANCIERO!N113,"") | O18: =IF(01_INPUTS!O17,_ENGINE_FINANCIERO!O113,"") | P18: =IF(01_INPUTS!P17,_ENGINE_FINANCIERO!P113,"") | ... S18: =IF(01_INPUTS!S17,_ENGINE_FINANCIERO!S113,"")
A19: Margen EBITDA (%) — sigue la vista de B2 (sin detalle por país, métrica derivada) | B19: % | G19: =IFERROR(G15/G7,"") -> 0.1051217 | H19: =IFERROR(H15/H7,"") | I19: =IF(01_INPUTS!I17,IFERROR(I15/I7,""),"") -> 0.24432294 | J19: =IF(01_INPUTS!J17,IFERROR(J15/J7,""),"") | K19: =IF(01_INPUTS!K17,IFERROR(K15/K7,""),"") | L19: =IF(01_INPUTS!L17,IFERROR(L15/L7,""),"") | M19: =IF(01_INPUTS!M17,IFERROR(M15/M7,""),"") | N19: =IF(01_INPUTS!N17,IFERROR(N15/N7,""),"") | O19: =IF(01_INPUTS!O17,IFERROR(O15/O7,""),"") | P19: =IF(01_INPUTS!P17,IFERROR(P15/P7,""),"") | ... S19: =IF(01_INPUTS!S17,IFERROR(S15/S7,""),"")
A20: Depreciación | B20: USD | G20: =CHOOSE(MATCH($B$2,$U$1:$U$5,0),_ENGINE_FINANCIERO!G163,_ENGINE_FINANCIERO!G20,_ENGINE_FINANCIERO!G67,_ENGINE_FINANCIERO!G114,_ENGINE_FINANCIERO!G163) -> 1203133800 | H20: =CHOOSE(MATCH($B$2,$U$1:$U$5,0),_ENGINE_FINANCIERO!H163,_ENGINE_FINANCIERO!H20,_ENGINE_FINANCIERO!H67,_ENGINE_FINANCIERO!H114,_ENGINE_FINANCIERO!H163) -> 1082820420 | I20: =IF(01_INPUTS!I17,CHOOSE(MATCH($B$2,$U$1:$U$5,0),_ENGINE_FINANCIERO!I163,_ENGINE_FINANCIERO!I20,_ENGINE_FINANCIERO!I67,_ENGINE_FINANCIERO!I114,_ENGINE_FINANCIERO!I163),"") -> 976338378 | J20: =IF(01_INPUTS!J17,CHOOSE(MATCH($B$2,$U$1:$U$5,0),_ENGINE_FINANCIERO!J163,_ENGINE_FINANCIERO!J20,_ENGINE_FINANCIERO!J67,_ENGINE_FINANCIERO!J114,_ENGINE_FINANCIERO!J163),"") | K20: =IF(01_INPUTS!K17,CHOOSE(MATCH($B$2,$U$1:$U$5,0),_ENGINE_FINANCIERO!K163,_ENGINE_FINANCIERO!K20,_ENGINE_FINANCIERO!K67,_ENGINE_FINANCIERO!K114,_ENGINE_FINANCIERO!K163),"") | L20: =IF(01_INPUTS!L17,CHOOSE(MATCH($B$2,$U$1:$U$5,0),_ENGINE_FINANCIERO!L163,_ENGINE_FINANCIERO!L20,_ENGINE_FINANCIERO!L67,_ENGINE_FINANCIERO!L114,_ENGINE_FINANCIERO!L163),"") | M20: =IF(01_INPUTS!M17,CHOOSE(MATCH($B$2,$U$1:$U$5,0),_ENGINE_FINANCIERO!M163,_ENGINE_FINANCIERO!M20,_ENGINE_FINANCIERO!M67,_ENGINE_FINANCIERO!M114,_ENGINE_FINANCIERO!M163),"") | N20: =IF(01_INPUTS!N17,CHOOSE(MATCH($B$2,$U$1:$U$5,0),_ENGINE_FINANCIERO!N163,_ENGINE_FINANCIERO!N20,_ENGINE_FINANCIERO!N67,_ENGINE_FINANCIERO!N114,_ENGINE_FINANCIERO!N163),"") | O20: =IF(01_INPUTS!O17,CHOOSE(MATCH($B$2,$U$1:$U$5,0),_ENGINE_FINANCIERO!O163,_ENGINE_FINANCIERO!O20,_ENGINE_FINANCIERO!O67,_ENGINE_FINANCIERO!O114,_ENGINE_FINANCIERO!O163),"") | P20: =IF(01_INPUTS!P17,CHOOSE(MATCH($B$2,$U$1:$U$5,0),_ENGINE_FINANCIERO!P163,_ENGINE_FINANCIERO!P20,_ENGINE_FINANCIERO!P67,_ENGINE_FINANCIERO!P114,_ENGINE_FINANCIERO!P163),"") | ... S20: =IF(01_INPUTS!S17,CHOOSE(MATCH($B$2,$U$1:$U$5,0),_ENGINE_FINANCIERO!S163,_ENGINE_FINANCIERO!S20,_ENGINE_FINANCIERO!S67,_ENGINE_FINANCIERO!S114,_ENGINE_FINANCIERO!S163),"")
A21: EE.UU. | B21: USD | G21: =_ENGINE_FINANCIERO!G20 -> 1005068400 | H21: =_ENGINE_FINANCIERO!H20 -> 904561560 | I21: =IF(01_INPUTS!I17,_ENGINE_FINANCIERO!I20,"") -> 815505404 | J21: =IF(01_INPUTS!J17,_ENGINE_FINANCIERO!J20,"") | K21: =IF(01_INPUTS!K17,_ENGINE_FINANCIERO!K20,"") | L21: =IF(01_INPUTS!L17,_ENGINE_FINANCIERO!L20,"") | M21: =IF(01_INPUTS!M17,_ENGINE_FINANCIERO!M20,"") | N21: =IF(01_INPUTS!N17,_ENGINE_FINANCIERO!N20,"") | O21: =IF(01_INPUTS!O17,_ENGINE_FINANCIERO!O20,"") | P21: =IF(01_INPUTS!P17,_ENGINE_FINANCIERO!P20,"") | ... S21: =IF(01_INPUTS!S17,_ENGINE_FINANCIERO!S20,"")
A22: China | B22: USD | G22: =_ENGINE_FINANCIERO!G67 -> 198065400 | H22: =_ENGINE_FINANCIERO!H67 -> 178258860 | I22: =IF(01_INPUTS!I17,_ENGINE_FINANCIERO!I67,"") -> 160832974 | J22: =IF(01_INPUTS!J17,_ENGINE_FINANCIERO!J67,"") | K22: =IF(01_INPUTS!K17,_ENGINE_FINANCIERO!K67,"") | L22: =IF(01_INPUTS!L17,_ENGINE_FINANCIERO!L67,"") | M22: =IF(01_INPUTS!M17,_ENGINE_FINANCIERO!M67,"") | N22: =IF(01_INPUTS!N17,_ENGINE_FINANCIERO!N67,"") | O22: =IF(01_INPUTS!O17,_ENGINE_FINANCIERO!O67,"") | P22: =IF(01_INPUTS!P17,_ENGINE_FINANCIERO!P67,"") | ... S22: =IF(01_INPUTS!S17,_ENGINE_FINANCIERO!S67,"")
A23: Europa | B23: USD | G23: =_ENGINE_FINANCIERO!G114 -> 0 | H23: =_ENGINE_FINANCIERO!H114 -> 0 | I23: =IF(01_INPUTS!I17,_ENGINE_FINANCIERO!I114,"") -> 0 | J23: =IF(01_INPUTS!J17,_ENGINE_FINANCIERO!J114,"") | K23: =IF(01_INPUTS!K17,_ENGINE_FINANCIERO!K114,"") | L23: =IF(01_INPUTS!L17,_ENGINE_FINANCIERO!L114,"") | M23: =IF(01_INPUTS!M17,_ENGINE_FINANCIERO!M114,"") | N23: =IF(01_INPUTS!N17,_ENGINE_FINANCIERO!N114,"") | O23: =IF(01_INPUTS!O17,_ENGINE_FINANCIERO!O114,"") | P23: =IF(01_INPUTS!P17,_ENGINE_FINANCIERO!P114,"") | ... S23: =IF(01_INPUTS!S17,_ENGINE_FINANCIERO!S114,"")
A24: EBIT | B24: USD | G24: =CHOOSE(MATCH($B$2,$U$1:$U$5,0),_ENGINE_FINANCIERO!G164,_ENGINE_FINANCIERO!G21,_ENGINE_FINANCIERO!G68,_ENGINE_FINANCIERO!G115,_ENGINE_FINANCIERO!G164) -> 2.948017e+09 | H24: =CHOOSE(MATCH($B$2,$U$1:$U$5,0),_ENGINE_FINANCIERO!H164,_ENGINE_FINANCIERO!H21,_ENGINE_FINANCIERO!H68,_ENGINE_FINANCIERO!H115,_ENGINE_FINANCIERO!H164) -> n/a | I24: =IF(01_INPUTS!I17,CHOOSE(MATCH($B$2,$U$1:$U$5,0),_ENGINE_FINANCIERO!I164,_ENGINE_FINANCIERO!I21,_ENGINE_FINANCIERO!I68,_ENGINE_FINANCIERO!I115,_ENGINE_FINANCIERO!I164),"") -> 1.7822091e+10 | J24: =IF(01_INPUTS!J17,CHOOSE(MATCH($B$2,$U$1:$U$5,0),_ENGINE_FINANCIERO!J164,_ENGINE_FINANCIERO!J21,_ENGINE_FINANCIERO!J68,_ENGINE_FINANCIERO!J115,_ENGINE_FINANCIERO!J164),"") | K24: =IF(01_INPUTS!K17,CHOOSE(MATCH($B$2,$U$1:$U$5,0),_ENGINE_FINANCIERO!K164,_ENGINE_FINANCIERO!K21,_ENGINE_FINANCIERO!K68,_ENGINE_FINANCIERO!K115,_ENGINE_FINANCIERO!K164),"") | L24: =IF(01_INPUTS!L17,CHOOSE(MATCH($B$2,$U$1:$U$5,0),_ENGINE_FINANCIERO!L164,_ENGINE_FINANCIERO!L21,_ENGINE_FINANCIERO!L68,_ENGINE_FINANCIERO!L115,_ENGINE_FINANCIERO!L164),"") | M24: =IF(01_INPUTS!M17,CHOOSE(MATCH($B$2,$U$1:$U$5,0),_ENGINE_FINANCIERO!M164,_ENGINE_FINANCIERO!M21,_ENGINE_FINANCIERO!M68,_ENGINE_FINANCIERO!M115,_ENGINE_FINANCIERO!M164),"") | N24: =IF(01_INPUTS!N17,CHOOSE(MATCH($B$2,$U$1:$U$5,0),_ENGINE_FINANCIERO!N164,_ENGINE_FINANCIERO!N21,_ENGINE_FINANCIERO!N68,_ENGINE_FINANCIERO!N115,_ENGINE_FINANCIERO!N164),"") | O24: =IF(01_INPUTS!O17,CHOOSE(MATCH($B$2,$U$1:$U$5,0),_ENGINE_FINANCIERO!O164,_ENGINE_FINANCIERO!O21,_ENGINE_FINANCIERO!O68,_ENGINE_FINANCIERO!O115,_ENGINE_FINANCIERO!O164),"") | P24: =IF(01_INPUTS!P17,CHOOSE(MATCH($B$2,$U$1:$U$5,0),_ENGINE_FINANCIERO!P164,_ENGINE_FINANCIERO!P21,_ENGINE_FINANCIERO!P68,_ENGINE_FINANCIERO!P115,_ENGINE_FINANCIERO!P164),"") | ... S24: =IF(01_INPUTS!S17,CHOOSE(MATCH($B$2,$U$1:$U$5,0),_ENGINE_FINANCIERO!S164,_ENGINE_FINANCIERO!S21,_ENGINE_FINANCIERO!S68,_ENGINE_FINANCIERO!S115,_ENGINE_FINANCIERO!S164),"")
A25: EE.UU. | B25: USD | G25: =_ENGINE_FINANCIERO!G21 -> -1005068400 | H25: =_ENGINE_FINANCIERO!H21 -> -967561560 | I25: =IF(01_INPUTS!I17,_ENGINE_FINANCIERO!I21,"") -> 3.2685815e+09 | J25: =IF(01_INPUTS!J17,_ENGINE_FINANCIERO!J21,"") | K25: =IF(01_INPUTS!K17,_ENGINE_FINANCIERO!K21,"") | L25: =IF(01_INPUTS!L17,_ENGINE_FINANCIERO!L21,"") | M25: =IF(01_INPUTS!M17,_ENGINE_FINANCIERO!M21,"") | N25: =IF(01_INPUTS!N17,_ENGINE_FINANCIERO!N21,"") | O25: =IF(01_INPUTS!O17,_ENGINE_FINANCIERO!O21,"") | P25: =IF(01_INPUTS!P17,_ENGINE_FINANCIERO!P21,"") | ... S25: =IF(01_INPUTS!S17,_ENGINE_FINANCIERO!S21,"")
A26: China | B26: USD | G26: =_ENGINE_FINANCIERO!G68 -> -198065400 | H26: =_ENGINE_FINANCIERO!H68 -> -273258860 | I26: =IF(01_INPUTS!I17,_ENGINE_FINANCIERO!I68,"") -> 3.4036597e+09 | J26: =IF(01_INPUTS!J17,_ENGINE_FINANCIERO!J68,"") | K26: =IF(01_INPUTS!K17,_ENGINE_FINANCIERO!K68,"") | L26: =IF(01_INPUTS!L17,_ENGINE_FINANCIERO!L68,"") | M26: =IF(01_INPUTS!M17,_ENGINE_FINANCIERO!M68,"") | N26: =IF(01_INPUTS!N17,_ENGINE_FINANCIERO!N68,"") | O26: =IF(01_INPUTS!O17,_ENGINE_FINANCIERO!O68,"") | P26: =IF(01_INPUTS!P17,_ENGINE_FINANCIERO!P68,"") | ... S26: =IF(01_INPUTS!S17,_ENGINE_FINANCIERO!S68,"")
A27: Europa | B27: USD | G27: =_ENGINE_FINANCIERO!G115 -> 0 | H27: =_ENGINE_FINANCIERO!H115 -> -20000000 | I27: =IF(01_INPUTS!I17,_ENGINE_FINANCIERO!I115,"") -> 1.114985e+10 | J27: =IF(01_INPUTS!J17,_ENGINE_FINANCIERO!J115,"") | K27: =IF(01_INPUTS!K17,_ENGINE_FINANCIERO!K115,"") | L27: =IF(01_INPUTS!L17,_ENGINE_FINANCIERO!L115,"") | M27: =IF(01_INPUTS!M17,_ENGINE_FINANCIERO!M115,"") | N27: =IF(01_INPUTS!N17,_ENGINE_FINANCIERO!N115,"") | O27: =IF(01_INPUTS!O17,_ENGINE_FINANCIERO!O115,"") | P27: =IF(01_INPUTS!P17,_ENGINE_FINANCIERO!P115,"") | ... S27: =IF(01_INPUTS!S17,_ENGINE_FINANCIERO!S115,"")
A28: Gastos financieros netos | B28: USD | G28: =CHOOSE(MATCH($B$2,$U$1:$U$5,0),_ENGINE_FINANCIERO!G165,_ENGINE_FINANCIERO!G22,_ENGINE_FINANCIERO!G69,_ENGINE_FINANCIERO!G116,_ENGINE_FINANCIERO!G165) -> 6.4270758e+08 | H28: =CHOOSE(MATCH($B$2,$U$1:$U$5,0),_ENGINE_FINANCIERO!H165,_ENGINE_FINANCIERO!H22,_ENGINE_FINANCIERO!H69,_ENGINE_FINANCIERO!H116,_ENGINE_FINANCIERO!H165) -> n/a | I28: =IF(01_INPUTS!I17,CHOOSE(MATCH($B$2,$U$1:$U$5,0),_ENGINE_FINANCIERO!I165,_ENGINE_FINANCIERO!I22,_ENGINE_FINANCIERO!I69,_ENGINE_FINANCIERO!I116,_ENGINE_FINANCIERO!I165),"") -> 3.7475015e+08 | J28: =IF(01_INPUTS!J17,CHOOSE(MATCH($B$2,$U$1:$U$5,0),_ENGINE_FINANCIERO!J165,_ENGINE_FINANCIERO!J22,_ENGINE_FINANCIERO!J69,_ENGINE_FINANCIERO!J116,_ENGINE_FINANCIERO!J165),"") | K28: =IF(01_INPUTS!K17,CHOOSE(MATCH($B$2,$U$1:$U$5,0),_ENGINE_FINANCIERO!K165,_ENGINE_FINANCIERO!K22,_ENGINE_FINANCIERO!K69,_ENGINE_FINANCIERO!K116,_ENGINE_FINANCIERO!K165),"") | L28: =IF(01_INPUTS!L17,CHOOSE(MATCH($B$2,$U$1:$U$5,0),_ENGINE_FINANCIERO!L165,_ENGINE_FINANCIERO!L22,_ENGINE_FINANCIERO!L69,_ENGINE_FINANCIERO!L116,_ENGINE_FINANCIERO!L165),"") | M28: =IF(01_INPUTS!M17,CHOOSE(MATCH($B$2,$U$1:$U$5,0),_ENGINE_FINANCIERO!M165,_ENGINE_FINANCIERO!M22,_ENGINE_FINANCIERO!M69,_ENGINE_FINANCIERO!M116,_ENGINE_FINANCIERO!M165),"") | N28: =IF(01_INPUTS!N17,CHOOSE(MATCH($B$2,$U$1:$U$5,0),_ENGINE_FINANCIERO!N165,_ENGINE_FINANCIERO!N22,_ENGINE_FINANCIERO!N69,_ENGINE_FINANCIERO!N116,_ENGINE_FINANCIERO!N165),"") | O28: =IF(01_INPUTS!O17,CHOOSE(MATCH($B$2,$U$1:$U$5,0),_ENGINE_FINANCIERO!O165,_ENGINE_FINANCIERO!O22,_ENGINE_FINANCIERO!O69,_ENGINE_FINANCIERO!O116,_ENGINE_FINANCIERO!O165),"") | P28: =IF(01_INPUTS!P17,CHOOSE(MATCH($B$2,$U$1:$U$5,0),_ENGINE_FINANCIERO!P165,_ENGINE_FINANCIERO!P22,_ENGINE_FINANCIERO!P69,_ENGINE_FINANCIERO!P116,_ENGINE_FINANCIERO!P165),"") | ... S28: =IF(01_INPUTS!S17,CHOOSE(MATCH($B$2,$U$1:$U$5,0),_ENGINE_FINANCIERO!S165,_ENGINE_FINANCIERO!S22,_ENGINE_FINANCIERO!S69,_ENGINE_FINANCIERO!S116,_ENGINE_FINANCIERO!S165),"")
A29: EE.UU. | B29: USD | G29: =_ENGINE_FINANCIERO!G22 -> 5.2918124e+08 | H29: =_ENGINE_FINANCIERO!H22 -> 4.5358412e+08 | I29: =IF(01_INPUTS!I17,_ENGINE_FINANCIERO!I22,"") -> 5.5138856e+08 | J29: =IF(01_INPUTS!J17,_ENGINE_FINANCIERO!J22,"") | K29: =IF(01_INPUTS!K17,_ENGINE_FINANCIERO!K22,"") | L29: =IF(01_INPUTS!L17,_ENGINE_FINANCIERO!L22,"") | M29: =IF(01_INPUTS!M17,_ENGINE_FINANCIERO!M22,"") | N29: =IF(01_INPUTS!N17,_ENGINE_FINANCIERO!N22,"") | O29: =IF(01_INPUTS!O17,_ENGINE_FINANCIERO!O22,"") | P29: =IF(01_INPUTS!P17,_ENGINE_FINANCIERO!P22,"") | ... S29: =IF(01_INPUTS!S17,_ENGINE_FINANCIERO!S22,"")
A30: China | B30: USD | G30: =_ENGINE_FINANCIERO!G69 -> 1.19425e+08 | H30: =_ENGINE_FINANCIERO!H69 -> -72726647 | I30: =IF(01_INPUTS!I17,_ENGINE_FINANCIERO!I69,"") -> -1.2537651e+08 | J30: =IF(01_INPUTS!J17,_ENGINE_FINANCIERO!J69,"") | K30: =IF(01_INPUTS!K17,_ENGINE_FINANCIERO!K69,"") | L30: =IF(01_INPUTS!L17,_ENGINE_FINANCIERO!L69,"") | M30: =IF(01_INPUTS!M17,_ENGINE_FINANCIERO!M69,"") | N30: =IF(01_INPUTS!N17,_ENGINE_FINANCIERO!N69,"") | O30: =IF(01_INPUTS!O17,_ENGINE_FINANCIERO!O69,"") | P30: =IF(01_INPUTS!P17,_ENGINE_FINANCIERO!P69,"") | ... S30: =IF(01_INPUTS!S17,_ENGINE_FINANCIERO!S69,"")
A31: Europa | B31: USD | G31: =_ENGINE_FINANCIERO!G116 -> -5898652.7 | H31: =_ENGINE_FINANCIERO!H116 -> -43304006 | I31: =IF(01_INPUTS!I17,_ENGINE_FINANCIERO!I116,"") -> -51261897 | J31: =IF(01_INPUTS!J17,_ENGINE_FINANCIERO!J116,"") | K31: =IF(01_INPUTS!K17,_ENGINE_FINANCIERO!K116,"") | L31: =IF(01_INPUTS!L17,_ENGINE_FINANCIERO!L116,"") | M31: =IF(01_INPUTS!M17,_ENGINE_FINANCIERO!M116,"") | N31: =IF(01_INPUTS!N17,_ENGINE_FINANCIERO!N116,"") | O31: =IF(01_INPUTS!O17,_ENGINE_FINANCIERO!O116,"") | P31: =IF(01_INPUTS!P17,_ENGINE_FINANCIERO!P116,"") | ... S31: =IF(01_INPUTS!S17,_ENGINE_FINANCIERO!S116,"")
A32: Beneficio antes de impuestos | B32: USD | G32: =CHOOSE(MATCH($B$2,$U$1:$U$5,0),_ENGINE_FINANCIERO!G166,_ENGINE_FINANCIERO!G23,_ENGINE_FINANCIERO!G70,_ENGINE_FINANCIERO!G117,_ENGINE_FINANCIERO!G166) -> 2.3053094e+09 | H32: =CHOOSE(MATCH($B$2,$U$1:$U$5,0),_ENGINE_FINANCIERO!H166,_ENGINE_FINANCIERO!H23,_ENGINE_FINANCIERO!H70,_ENGINE_FINANCIERO!H117,_ENGINE_FINANCIERO!H166) -> n/a | I32: =IF(01_INPUTS!I17,CHOOSE(MATCH($B$2,$U$1:$U$5,0),_ENGINE_FINANCIERO!I166,_ENGINE_FINANCIERO!I23,_ENGINE_FINANCIERO!I70,_ENGINE_FINANCIERO!I117,_ENGINE_FINANCIERO!I166),"") -> 1.7447341e+10 | J32: =IF(01_INPUTS!J17,CHOOSE(MATCH($B$2,$U$1:$U$5,0),_ENGINE_FINANCIERO!J166,_ENGINE_FINANCIERO!J23,_ENGINE_FINANCIERO!J70,_ENGINE_FINANCIERO!J117,_ENGINE_FINANCIERO!J166),"") | K32: =IF(01_INPUTS!K17,CHOOSE(MATCH($B$2,$U$1:$U$5,0),_ENGINE_FINANCIERO!K166,_ENGINE_FINANCIERO!K23,_ENGINE_FINANCIERO!K70,_ENGINE_FINANCIERO!K117,_ENGINE_FINANCIERO!K166),"") | L32: =IF(01_INPUTS!L17,CHOOSE(MATCH($B$2,$U$1:$U$5,0),_ENGINE_FINANCIERO!L166,_ENGINE_FINANCIERO!L23,_ENGINE_FINANCIERO!L70,_ENGINE_FINANCIERO!L117,_ENGINE_FINANCIERO!L166),"") | M32: =IF(01_INPUTS!M17,CHOOSE(MATCH($B$2,$U$1:$U$5,0),_ENGINE_FINANCIERO!M166,_ENGINE_FINANCIERO!M23,_ENGINE_FINANCIERO!M70,_ENGINE_FINANCIERO!M117,_ENGINE_FINANCIERO!M166),"") | N32: =IF(01_INPUTS!N17,CHOOSE(MATCH($B$2,$U$1:$U$5,0),_ENGINE_FINANCIERO!N166,_ENGINE_FINANCIERO!N23,_ENGINE_FINANCIERO!N70,_ENGINE_FINANCIERO!N117,_ENGINE_FINANCIERO!N166),"") | O32: =IF(01_INPUTS!O17,CHOOSE(MATCH($B$2,$U$1:$U$5,0),_ENGINE_FINANCIERO!O166,_ENGINE_FINANCIERO!O23,_ENGINE_FINANCIERO!O70,_ENGINE_FINANCIERO!O117,_ENGINE_FINANCIERO!O166),"") | P32: =IF(01_INPUTS!P17,CHOOSE(MATCH($B$2,$U$1:$U$5,0),_ENGINE_FINANCIERO!P166,_ENGINE_FINANCIERO!P23,_ENGINE_FINANCIERO!P70,_ENGINE_FINANCIERO!P117,_ENGINE_FINANCIERO!P166),"") | ... S32: =IF(01_INPUTS!S17,CHOOSE(MATCH($B$2,$U$1:$U$5,0),_ENGINE_FINANCIERO!S166,_ENGINE_FINANCIERO!S23,_ENGINE_FINANCIERO!S70,_ENGINE_FINANCIERO!S117,_ENGINE_FINANCIERO!S166),"")
A33: EE.UU. | B33: USD | G33: =_ENGINE_FINANCIERO!G23 -> 9.6797274e+08 | H33: =_ENGINE_FINANCIERO!H23 -> 1.5018073e+09 | I33: =IF(01_INPUTS!I17,_ENGINE_FINANCIERO!I23,"") -> 2.7171929e+09 | J33: =IF(01_INPUTS!J17,_ENGINE_FINANCIERO!J23,"") | K33: =IF(01_INPUTS!K17,_ENGINE_FINANCIERO!K23,"") | L33: =IF(01_INPUTS!L17,_ENGINE_FINANCIERO!L23,"") | M33: =IF(01_INPUTS!M17,_ENGINE_FINANCIERO!M23,"") | N33: =IF(01_INPUTS!N17,_ENGINE_FINANCIERO!N23,"") | O33: =IF(01_INPUTS!O17,_ENGINE_FINANCIERO!O23,"") | P33: =IF(01_INPUTS!P17,_ENGINE_FINANCIERO!P23,"") | ... S33: =IF(01_INPUTS!S17,_ENGINE_FINANCIERO!S23,"")
A34: China | B34: USD | G34: =_ENGINE_FINANCIERO!G70 -> 5.1717431e+08 | H34: =_ENGINE_FINANCIERO!H70 -> 2.0651992e+09 | I34: =IF(01_INPUTS!I17,_ENGINE_FINANCIERO!I70,"") -> 3.5290362e+09 | J34: =IF(01_INPUTS!J17,_ENGINE_FINANCIERO!J70,"") | K34: =IF(01_INPUTS!K17,_ENGINE_FINANCIERO!K70,"") | L34: =IF(01_INPUTS!L17,_ENGINE_FINANCIERO!L70,"") | M34: =IF(01_INPUTS!M17,_ENGINE_FINANCIERO!M70,"") | N34: =IF(01_INPUTS!N17,_ENGINE_FINANCIERO!N70,"") | O34: =IF(01_INPUTS!O17,_ENGINE_FINANCIERO!O70,"") | P34: =IF(01_INPUTS!P17,_ENGINE_FINANCIERO!P70,"") | ... S34: =IF(01_INPUTS!S17,_ENGINE_FINANCIERO!S70,"")
A35: Europa | B35: USD | G35: =_ENGINE_FINANCIERO!G117 -> 8.2016234e+08 | H35: =_ENGINE_FINANCIERO!H117 -> 1.2178457e+09 | I35: =IF(01_INPUTS!I17,_ENGINE_FINANCIERO!I117,"") -> 1.1201112e+10 | J35: =IF(01_INPUTS!J17,_ENGINE_FINANCIERO!J117,"") | K35: =IF(01_INPUTS!K17,_ENGINE_FINANCIERO!K117,"") | L35: =IF(01_INPUTS!L17,_ENGINE_FINANCIERO!L117,"") | M35: =IF(01_INPUTS!M17,_ENGINE_FINANCIERO!M117,"") | N35: =IF(01_INPUTS!N17,_ENGINE_FINANCIERO!N117,"") | O35: =IF(01_INPUTS!O17,_ENGINE_FINANCIERO!O117,"") | P35: =IF(01_INPUTS!P17,_ENGINE_FINANCIERO!P117,"") | ... S35: =IF(01_INPUTS!S17,_ENGINE_FINANCIERO!S117,"")
A36: Impuesto sobre el beneficio | B36: USD | G36: =CHOOSE(MATCH($B$2,$U$1:$U$5,0),_ENGINE_FINANCIERO!G167,_ENGINE_FINANCIERO!G28,_ENGINE_FINANCIERO!G75,_ENGINE_FINANCIERO!G122,_ENGINE_FINANCIERO!G167) -> 5.6369141e+08 | H36: =CHOOSE(MATCH($B$2,$U$1:$U$5,0),_ENGINE_FINANCIERO!H167,_ENGINE_FINANCIERO!H28,_ENGINE_FINANCIERO!H75,_ENGINE_FINANCIERO!H122,_ENGINE_FINANCIERO!H167) -> n/a | I36: =IF(01_INPUTS!I17,CHOOSE(MATCH($B$2,$U$1:$U$5,0),_ENGINE_FINANCIERO!I167,_ENGINE_FINANCIERO!I28,_ENGINE_FINANCIERO!I75,_ENGINE_FINANCIERO!I122,_ENGINE_FINANCIERO!I167),"") -> 3.832275e+09 | J36: =IF(01_INPUTS!J17,CHOOSE(MATCH($B$2,$U$1:$U$5,0),_ENGINE_FINANCIERO!J167,_ENGINE_FINANCIERO!J28,_ENGINE_FINANCIERO!J75,_ENGINE_FINANCIERO!J122,_ENGINE_FINANCIERO!J167),"") | K36: =IF(01_INPUTS!K17,CHOOSE(MATCH($B$2,$U$1:$U$5,0),_ENGINE_FINANCIERO!K167,_ENGINE_FINANCIERO!K28,_ENGINE_FINANCIERO!K75,_ENGINE_FINANCIERO!K122,_ENGINE_FINANCIERO!K167),"") | L36: =IF(01_INPUTS!L17,CHOOSE(MATCH($B$2,$U$1:$U$5,0),_ENGINE_FINANCIERO!L167,_ENGINE_FINANCIERO!L28,_ENGINE_FINANCIERO!L75,_ENGINE_FINANCIERO!L122,_ENGINE_FINANCIERO!L167),"") | M36: =IF(01_INPUTS!M17,CHOOSE(MATCH($B$2,$U$1:$U$5,0),_ENGINE_FINANCIERO!M167,_ENGINE_FINANCIERO!M28,_ENGINE_FINANCIERO!M75,_ENGINE_FINANCIERO!M122,_ENGINE_FINANCIERO!M167),"") | N36: =IF(01_INPUTS!N17,CHOOSE(MATCH($B$2,$U$1:$U$5,0),_ENGINE_FINANCIERO!N167,_ENGINE_FINANCIERO!N28,_ENGINE_FINANCIERO!N75,_ENGINE_FINANCIERO!N122,_ENGINE_FINANCIERO!N167),"") | O36: =IF(01_INPUTS!O17,CHOOSE(MATCH($B$2,$U$1:$U$5,0),_ENGINE_FINANCIERO!O167,_ENGINE_FINANCIERO!O28,_ENGINE_FINANCIERO!O75,_ENGINE_FINANCIERO!O122,_ENGINE_FINANCIERO!O167),"") | P36: =IF(01_INPUTS!P17,CHOOSE(MATCH($B$2,$U$1:$U$5,0),_ENGINE_FINANCIERO!P167,_ENGINE_FINANCIERO!P28,_ENGINE_FINANCIERO!P75,_ENGINE_FINANCIERO!P122,_ENGINE_FINANCIERO!P167),"") | ... S36: =IF(01_INPUTS!S17,CHOOSE(MATCH($B$2,$U$1:$U$5,0),_ENGINE_FINANCIERO!S167,_ENGINE_FINANCIERO!S28,_ENGINE_FINANCIERO!S75,_ENGINE_FINANCIERO!S122,_ENGINE_FINANCIERO!S167),"")
A37: EE.UU. | B37: USD | G37: =_ENGINE_FINANCIERO!G28 -> 2.12954e+08 | H37: =_ENGINE_FINANCIERO!H28 -> 3.3039761e+08 | I37: =IF(01_INPUTS!I17,_ENGINE_FINANCIERO!I28,"") -> 5.9778245e+08 | J37: =IF(01_INPUTS!J17,_ENGINE_FINANCIERO!J28,"") | K37: =IF(01_INPUTS!K17,_ENGINE_FINANCIERO!K28,"") | L37: =IF(01_INPUTS!L17,_ENGINE_FINANCIERO!L28,"") | M37: =IF(01_INPUTS!M17,_ENGINE_FINANCIERO!M28,"") | N37: =IF(01_INPUTS!N17,_ENGINE_FINANCIERO!N28,"") | O37: =IF(01_INPUTS!O17,_ENGINE_FINANCIERO!O28,"") | P37: =IF(01_INPUTS!P17,_ENGINE_FINANCIERO!P28,"") | ... S37: =IF(01_INPUTS!S17,_ENGINE_FINANCIERO!S28,"")
A38: China | B38: USD | G38: =_ENGINE_FINANCIERO!G75 -> 1.2929358e+08 | H38: =_ENGINE_FINANCIERO!H75 -> 5.1629981e+08 | I38: =IF(01_INPUTS!I17,_ENGINE_FINANCIERO!I75,"") -> 8.8225905e+08 | J38: =IF(01_INPUTS!J17,_ENGINE_FINANCIERO!J75,"") | K38: =IF(01_INPUTS!K17,_ENGINE_FINANCIERO!K75,"") | L38: =IF(01_INPUTS!L17,_ENGINE_FINANCIERO!L75,"") | M38: =IF(01_INPUTS!M17,_ENGINE_FINANCIERO!M75,"") | N38: =IF(01_INPUTS!N17,_ENGINE_FINANCIERO!N75,"") | O38: =IF(01_INPUTS!O17,_ENGINE_FINANCIERO!O75,"") | P38: =IF(01_INPUTS!P17,_ENGINE_FINANCIERO!P75,"") | ... S38: =IF(01_INPUTS!S17,_ENGINE_FINANCIERO!S75,"")
A39: Europa | B39: USD | G39: =_ENGINE_FINANCIERO!G122 -> 2.2144383e+08 | H39: =_ENGINE_FINANCIERO!H122 -> 3.2881833e+08 | I39: =IF(01_INPUTS!I17,_ENGINE_FINANCIERO!I122,"") -> 2.3522335e+09 | J39: =IF(01_INPUTS!J17,_ENGINE_FINANCIERO!J122,"") | K39: =IF(01_INPUTS!K17,_ENGINE_FINANCIERO!K122,"") | L39: =IF(01_INPUTS!L17,_ENGINE_FINANCIERO!L122,"") | M39: =IF(01_INPUTS!M17,_ENGINE_FINANCIERO!M122,"") | N39: =IF(01_INPUTS!N17,_ENGINE_FINANCIERO!N122,"") | O39: =IF(01_INPUTS!O17,_ENGINE_FINANCIERO!O122,"") | P39: =IF(01_INPUTS!P17,_ENGINE_FINANCIERO!P122,"") | ... S39: =IF(01_INPUTS!S17,_ENGINE_FINANCIERO!S122,"")
A40: Beneficio de la ronda (neto) | B40: USD | G40: =CHOOSE(MATCH($B$2,$U$1:$U$5,0),_ENGINE_FINANCIERO!G168,_ENGINE_FINANCIERO!G29,_ENGINE_FINANCIERO!G76,_ENGINE_FINANCIERO!G123,_ENGINE_FINANCIERO!G168) -> 1.741618e+09 | H40: =CHOOSE(MATCH($B$2,$U$1:$U$5,0),_ENGINE_FINANCIERO!H168,_ENGINE_FINANCIERO!H29,_ENGINE_FINANCIERO!H76,_ENGINE_FINANCIERO!H123,_ENGINE_FINANCIERO!H168) -> 3.6093365e+09 | I40: =IF(01_INPUTS!I17,CHOOSE(MATCH($B$2,$U$1:$U$5,0),_ENGINE_FINANCIERO!I168,_ENGINE_FINANCIERO!I29,_ENGINE_FINANCIERO!I76,_ENGINE_FINANCIERO!I123,_ENGINE_FINANCIERO!I168),"") -> 1.3615066e+10 | J40: =IF(01_INPUTS!J17,CHOOSE(MATCH($B$2,$U$1:$U$5,0),_ENGINE_FINANCIERO!J168,_ENGINE_FINANCIERO!J29,_ENGINE_FINANCIERO!J76,_ENGINE_FINANCIERO!J123,_ENGINE_FINANCIERO!J168),"") | K40: =IF(01_INPUTS!K17,CHOOSE(MATCH($B$2,$U$1:$U$5,0),_ENGINE_FINANCIERO!K168,_ENGINE_FINANCIERO!K29,_ENGINE_FINANCIERO!K76,_ENGINE_FINANCIERO!K123,_ENGINE_FINANCIERO!K168),"") | L40: =IF(01_INPUTS!L17,CHOOSE(MATCH($B$2,$U$1:$U$5,0),_ENGINE_FINANCIERO!L168,_ENGINE_FINANCIERO!L29,_ENGINE_FINANCIERO!L76,_ENGINE_FINANCIERO!L123,_ENGINE_FINANCIERO!L168),"") | M40: =IF(01_INPUTS!M17,CHOOSE(MATCH($B$2,$U$1:$U$5,0),_ENGINE_FINANCIERO!M168,_ENGINE_FINANCIERO!M29,_ENGINE_FINANCIERO!M76,_ENGINE_FINANCIERO!M123,_ENGINE_FINANCIERO!M168),"") | N40: =IF(01_INPUTS!N17,CHOOSE(MATCH($B$2,$U$1:$U$5,0),_ENGINE_FINANCIERO!N168,_ENGINE_FINANCIERO!N29,_ENGINE_FINANCIERO!N76,_ENGINE_FINANCIERO!N123,_ENGINE_FINANCIERO!N168),"") | O40: =IF(01_INPUTS!O17,CHOOSE(MATCH($B$2,$U$1:$U$5,0),_ENGINE_FINANCIERO!O168,_ENGINE_FINANCIERO!O29,_ENGINE_FINANCIERO!O76,_ENGINE_FINANCIERO!O123,_ENGINE_FINANCIERO!O168),"") | P40: =IF(01_INPUTS!P17,CHOOSE(MATCH($B$2,$U$1:$U$5,0),_ENGINE_FINANCIERO!P168,_ENGINE_FINANCIERO!P29,_ENGINE_FINANCIERO!P76,_ENGINE_FINANCIERO!P123,_ENGINE_FINANCIERO!P168),"") | ... S40: =IF(01_INPUTS!S17,CHOOSE(MATCH($B$2,$U$1:$U$5,0),_ENGINE_FINANCIERO!S168,_ENGINE_FINANCIERO!S29,_ENGINE_FINANCIERO!S76,_ENGINE_FINANCIERO!S123,_ENGINE_FINANCIERO!S168),"")
...

Sheet 03_RATIOS
A1: 03_RATIOS — Ratios de crecimiento, rentabilidad, financieros y operativos (GLOBAL, por ronda)
A3: Concepto | B3: Unidad | G3: R0 | H3: R1 | I3: R2 | J3: R3 | K3: R4 | L3: R5 | M3: R6 | N3: R7 | O3: R8 | P3: R9 | Q3: R10 | R3: R11 | S3: R12
A4: CRECIMIENTO
A5: Crecimiento de Ingresos vs. ronda anterior | B5: % | G5: n/a (ver 02_ESTADOS_PROYECTADOS) | H5: n/a (ver 02_ESTADOS_PROYECTADOS) | I5: =IF(01_INPUTS!I17,IFERROR((_ENGINE_FINANCIERO!I160-_ENGINE_FINANCIERO!H160)/_ENGINE_FINANCIERO!H160,""),"") | J5: =IF(01_INPUTS!J17,IFERROR((_ENGINE_FINANCIERO!J160-_ENGINE_FINANCIERO!I160)/_ENGINE_FINANCIERO!I160,""),"") | K5: =IF(01_INPUTS!K17,IFERROR((_ENGINE_FINANCIERO!K160-_ENGINE_FINANCIERO!J160)/_ENGINE_FINANCIERO!J160,""),"") | L5: =IF(01_INPUTS!L17,IFERROR((_ENGINE_FINANCIERO!L160-_ENGINE_FINANCIERO!K160)/_ENGINE_FINANCIERO!K160,""),"") | M5: =IF(01_INPUTS!M17,IFERROR((_ENGINE_FINANCIERO!M160-_ENGINE_FINANCIERO!L160)/_ENGINE_FINANCIERO!L160,""),"") | N5: =IF(01_INPUTS!N17,IFERROR((_ENGINE_FINANCIERO!N160-_ENGINE_FINANCIERO!M160)/_ENGINE_FINANCIERO!M160,""),"") | O5: =IF(01_INPUTS!O17,IFERROR((_ENGINE_FINANCIERO!O160-_ENGINE_FINANCIERO!N160)/_ENGINE_FINANCIERO!N160,""),"") | P5: =IF(01_INPUTS!P17,IFERROR((_ENGINE_FINANCIERO!P160-_ENGINE_FINANCIERO!O160)/_ENGINE_FINANCIERO!O160,""),"") | ... S5: =IF(01_INPUTS!S17,IFERROR((_ENGINE_FINANCIERO!S160-_ENGINE_FINANCIERO!R160)/_ENGINE_FINANCIERO!R160,""),"")
A6: RENTABILIDAD
A7: Margen EBITDA | B7: % | G7: n/a (ver 02_ESTADOS_PROYECTADOS) | H7: n/a (ver 02_ESTADOS_PROYECTADOS) | I7: =IF(01_INPUTS!I17,IFERROR(_ENGINE_FINANCIERO!I162/_ENGINE_FINANCIERO!I160,""),"") -> 0.24432294 | J7: =IF(01_INPUTS!J17,IFERROR(_ENGINE_FINANCIERO!J162/_ENGINE_FINANCIERO!J160,""),"") | K7: =IF(01_INPUTS!K17,IFERROR(_ENGINE_FINANCIERO!K162/_ENGINE_FINANCIERO!K160,""),"") | L7: =IF(01_INPUTS!L17,IFERROR(_ENGINE_FINANCIERO!L162/_ENGINE_FINANCIERO!L160,""),"") | M7: =IF(01_INPUTS!M17,IFERROR(_ENGINE_FINANCIERO!M162/_ENGINE_FINANCIERO!M160,""),"") | N7: =IF(01_INPUTS!N17,IFERROR(_ENGINE_FINANCIERO!N162/_ENGINE_FINANCIERO!N160,""),"") | O7: =IF(01_INPUTS!O17,IFERROR(_ENGINE_FINANCIERO!O162/_ENGINE_FINANCIERO!O160,""),"") | P7: =IF(01_INPUTS!P17,IFERROR(_ENGINE_FINANCIERO!P162/_ENGINE_FINANCIERO!P160,""),"") | ... S7: =IF(01_INPUTS!S17,IFERROR(_ENGINE_FINANCIERO!S162/_ENGINE_FINANCIERO!S160,""),"")
A8: ROS — Beneficio neto / Ingresos | B8: % | G8: n/a (ver 02_ESTADOS_PROYECTADOS) | H8: n/a (ver 02_ESTADOS_PROYECTADOS) | I8: =IF(01_INPUTS!I17,IFERROR(_ENGINE_FINANCIERO!I168/_ENGINE_FINANCIERO!I160,""),"") -> 0.17695483 | J8: =IF(01_INPUTS!J17,IFERROR(_ENGINE_FINANCIERO!J168/_ENGINE_FINANCIERO!J160,""),"") | K8: =IF(01_INPUTS!K17,IFERROR(_ENGINE_FINANCIERO!K168/_ENGINE_FINANCIERO!K160,""),"") | L8: =IF(01_INPUTS!L17,IFERROR(_ENGINE_FINANCIERO!L168/_ENGINE_FINANCIERO!L160,""),"") | M8: =IF(01_INPUTS!M17,IFERROR(_ENGINE_FINANCIERO!M168/_ENGINE_FINANCIERO!M160,""),"") | N8: =IF(01_INPUTS!N17,IFERROR(_ENGINE_FINANCIERO!N168/_ENGINE_FINANCIERO!N160,""),"") | O8: =IF(01_INPUTS!O17,IFERROR(_ENGINE_FINANCIERO!O168/_ENGINE_FINANCIERO!O160,""),"") | P8: =IF(01_INPUTS!P17,IFERROR(_ENGINE_FINANCIERO!P168/_ENGINE_FINANCIERO!P160,""),"") | ... S8: =IF(01_INPUTS!S17,IFERROR(_ENGINE_FINANCIERO!S168/_ENGINE_FINANCIERO!S160,""),"")
A9: ROE — Beneficio neto / Patrimonio promedio (apertura,cierre) | B9: % | G9: n/a (ver 02_ESTADOS_PROYECTADOS) | H9: n/a (ver 02_ESTADOS_PROYECTADOS) | I9: =IF(01_INPUTS!I17,IFERROR(_ENGINE_FINANCIERO!I168/((_ENGINE_FINANCIERO!H181+_ENGINE_FINANCIERO!I181)/2),""),"") -> 0.80465242 | J9: =IF(01_INPUTS!J17,IFERROR(_ENGINE_FINANCIERO!J168/((_ENGINE_FINANCIERO!I181+_ENGINE_FINANCIERO!J181)/2),""),"") | K9: =IF(01_INPUTS!K17,IFERROR(_ENGINE_FINANCIERO!K168/((_ENGINE_FINANCIERO!J181+_ENGINE_FINANCIERO!K181)/2),""),"") | L9: =IF(01_INPUTS!L17,IFERROR(_ENGINE_FINANCIERO!L168/((_ENGINE_FINANCIERO!K181+_ENGINE_FINANCIERO!L181)/2),""),"") | M9: =IF(01_INPUTS!M17,IFERROR(_ENGINE_FINANCIERO!M168/((_ENGINE_FINANCIERO!L181+_ENGINE_FINANCIERO!M181)/2),""),"") | N9: =IF(01_INPUTS!N17,IFERROR(_ENGINE_FINANCIERO!N168/((_ENGINE_FINANCIERO!M181+_ENGINE_FINANCIERO!N181)/2),""),"") | O9: =IF(01_INPUTS!O17,IFERROR(_ENGINE_FINANCIERO!O168/((_ENGINE_FINANCIERO!N181+_ENGINE_FINANCIERO!O181)/2),""),"") | P9: =IF(01_INPUTS!P17,IFERROR(_ENGINE_FINANCIERO!P168/((_ENGINE_FINANCIERO!O181+_ENGINE_FINANCIERO!P181)/2),""),"") | ... S9: =IF(01_INPUTS!S17,IFERROR(_ENGINE_FINANCIERO!S168/((_ENGINE_FINANCIERO!R181+_ENGINE_FINANCIERO!S181)/2),""),"")
A10: ROCE — EBIT / Capital empleado promedio (apertura,cierre) | B10: % | G10: n/a (ver 02_ESTADOS_PROYECTADOS) | H10: n/a (ver 02_ESTADOS_PROYECTADOS) | I10: =IF(01_INPUTS!I17,IFERROR(_ENGINE_FINANCIERO!I164/(((_ENGINE_FINANCIERO!H182+_ENGINE_FINANCIERO!H183+_ENGINE_FINANCIERO!H181)+(_ENGINE_FINANCIERO!I182+_ENGINE_FINANCIERO!I183+_ENGINE_FINANCIERO!I181))/2),""),"") -> 0.61838392 | J10: =IF(01_INPUTS!J17,IFERROR(_ENGINE_FINANCIERO!J164/(((_ENGINE_FINANCIERO!I182+_ENGINE_FINANCIERO!I183+_ENGINE_FINANCIERO!I181)+(_ENGINE_FINANCIERO!J182+_ENGINE_FINANCIERO!J183+_ENGINE_FINANCIERO!J181))/2),""),"") | K10: =IF(01_INPUTS!K17,IFERROR(_ENGINE_FINANCIERO!K164/(((_ENGINE_FINANCIERO!J182+_ENGINE_FINANCIERO!J183+_ENGINE_FINANCIERO!J181)+(_ENGINE_FINANCIERO!K182+_ENGINE_FINANCIERO!K183+_ENGINE_FINANCIERO!K181))/2),""),"") | L10: =IF(01_INPUTS!L17,IFERROR(_ENGINE_FINANCIERO!L164/(((_ENGINE_FINANCIERO!K182+_ENGINE_FINANCIERO!K183+_ENGINE_FINANCIERO!K181)+(_ENGINE_FINANCIERO!L182+_ENGINE_FINANCIERO!L183+_ENGINE_FINANCIERO!L181))/2),""),"") | M10: =IF(01_INPUTS!M17,IFERROR(_ENGINE_FINANCIERO!M164/(((_ENGINE_FINANCIERO!L182+_ENGINE_FINANCIERO!L183+_ENGINE_FINANCIERO!L181)+(_ENGINE_FINANCIERO!M182+_ENGINE_FINANCIERO!M183+_ENGINE_FINANCIERO!M181))/2),""),"") | N10: =IF(01_INPUTS!N17,IFERROR(_ENGINE_FINANCIERO!N164/(((_ENGINE_FINANCIERO!M182+_ENGINE_FINANCIERO!M183+_ENGINE_FINANCIERO!M181)+(_ENGINE_FINANCIERO!N182+_ENGINE_FINANCIERO!N183+_ENGINE_FINANCIERO!N181))/2),""),"") | O10: =IF(01_INPUTS!O17,IFERROR(_ENGINE_FINANCIERO!O164/(((_ENGINE_FINANCIERO!N182+_ENGINE_FINANCIERO!N183+_ENGINE_FINANCIERO!N181)+(_ENGINE_FINANCIERO!O182+_ENGINE_FINANCIERO!O183+_ENGINE_FINANCIERO!O181))/2),""),"") | P10: =IF(01_INPUTS!P17,IFERROR(_ENGINE_FINANCIERO!P164/(((_ENGINE_FINANCIERO!O182+_ENGINE_FINANCIERO!O183+_ENGINE_FINANCIERO!O181)+(_ENGINE_FINANCIERO!P182+_ENGINE_FINANCIERO!P183+_ENGINE_FINANCIERO!P181))/2),""),"") | ... S10: =IF(01_INPUTS!S17,IFERROR(_ENGINE_FINANCIERO!S164/(((_ENGINE_FINANCIERO!R182+_ENGINE_FINANCIERO!R183+_ENGINE_FINANCIERO!R181)+(_ENGINE_FINANCIERO!S182+_ENGINE_FINANCIERO!S183+_ENGINE_FINANCIERO!S181))/2),""),"")
A11: WACC (proxy simplificado) | B11: % | G11: n/a (ver 02_ESTADOS_PROYECTADOS) | H11: n/a (ver 02_ESTADOS_PROYECTADOS) | I11: =IF(01_INPUTS!I17,IFERROR((_ENGINE_FINANCIERO!I181/(_ENGINE_FINANCIERO!I182+_ENGINE_FINANCIERO!I183+_ENGINE_FINANCIERO!I181))*0.12+((_ENGINE_FINANCIERO!I182+_ENGINE_FINANCIERO!I183)/(_ENGINE_FINANCIERO!I182+_ENGINE_FINANCIERO!I183+_ENGINE_FINANCIERO!I181))*01_INPUTS!I29*(1-01_INPUTS!I23),""),"") -> 0.0917563 | J11: =IF(01_INPUTS!J17,IFERROR((_ENGINE_FINANCIERO!J181/(_ENGINE_FINANCIERO!J182+_ENGINE_FINANCIERO!J183+_ENGINE_FINANCIERO!J181))*0.12+((_ENGINE_FINANCIERO!J182+_ENGINE_FINANCIERO!J183)/(_ENGINE_FINANCIERO!J182+_ENGINE_FINANCIERO!J183+_ENGINE_FINANCIERO!J181))*01_INPUTS!J29*(1-01_INPUTS!J23),""),"") | K11: =IF(01_INPUTS!K17,IFERROR((_ENGINE_FINANCIERO!K181/(_ENGINE_FINANCIERO!K182+_ENGINE_FINANCIERO!K183+_ENGINE_FINANCIERO!K181))*0.12+((_ENGINE_FINANCIERO!K182+_ENGINE_FINANCIERO!K183)/(_ENGINE_FINANCIERO!K182+_ENGINE_FINANCIERO!K183+_ENGINE_FINANCIERO!K181))*01_INPUTS!K29*(1-01_INPUTS!K23),""),"") | L11: =IF(01_INPUTS!L17,IFERROR((_ENGINE_FINANCIERO!L181/(_ENGINE_FINANCIERO!L182+_ENGINE_FINANCIERO!L183+_ENGINE_FINANCIERO!L181))*0.12+((_ENGINE_FINANCIERO!L182+_ENGINE_FINANCIERO!L183)/(_ENGINE_FINANCIERO!L182+_ENGINE_FINANCIERO!L183+_ENGINE_FINANCIERO!L181))*01_INPUTS!L29*(1-01_INPUTS!L23),""),"") | M11: =IF(01_INPUTS!M17,IFERROR((_ENGINE_FINANCIERO!M181/(_ENGINE_FINANCIERO!M182+_ENGINE_FINANCIERO!M183+_ENGINE_FINANCIERO!M181))*0.12+((_ENGINE_FINANCIERO!M182+_ENGINE_FINANCIERO!M183)/(_ENGINE_FINANCIERO!M182+_ENGINE_FINANCIERO!M183+_ENGINE_FINANCIERO!M181))*01_INPUTS!M29*(1-01_INPUTS!M23),""),"") | N11: =IF(01_INPUTS!N17,IFERROR((_ENGINE_FINANCIERO!N181/(_ENGINE_FINANCIERO!N182+_ENGINE_FINANCIERO!N183+_ENGINE_FINANCIERO!N181))*0.12+((_ENGINE_FINANCIERO!N182+_ENGINE_FINANCIERO!N183)/(_ENGINE_FINANCIERO!N182+_ENGINE_FINANCIERO!N183+_ENGINE_FINANCIERO!N181))*01_INPUTS!N29*(1-01_INPUTS!N23),""),"") | O11: =IF(01_INPUTS!O17,IFERROR((_ENGINE_FINANCIERO!O181/(_ENGINE_FINANCIERO!O182+_ENGINE_FINANCIERO!O183+_ENGINE_FINANCIERO!O181))*0.12+((_ENGINE_FINANCIERO!O182+_ENGINE_FINANCIERO!O183)/(_ENGINE_FINANCIERO!O182+_ENGINE_FINANCIERO!O183+_ENGINE_FINANCIERO!O181))*01_INPUTS!O29*(1-01_INPUTS!O23),""),"") | P11: =IF(01_INPUTS!P17,IFERROR((_ENGINE_FINANCIERO!P181/(_ENGINE_FINANCIERO!P182+_ENGINE_FINANCIERO!P183+_ENGINE_FINANCIERO!P181))*0.12+((_ENGINE_FINANCIERO!P182+_ENGINE_FINANCIERO!P183)/(_ENGINE_FINANCIERO!P182+_ENGINE_FINANCIERO!P183+_ENGINE_FINANCIERO!P181))*01_INPUTS!P29*(1-01_INPUTS!P23),""),"") | ... S11: =IF(01_INPUTS!S17,IFERROR((_ENGINE_FINANCIERO!S181/(_ENGINE_FINANCIERO!S182+_ENGINE_FINANCIERO!S183+_ENGINE_FINANCIERO!S181))*0.12+((_ENGINE_FINANCIERO!S182+_ENGINE_FINANCIERO!S183)/(_ENGINE_FINANCIERO!S182+_ENGINE_FINANCIERO!S183+_ENGINE_FINANCIERO!S181))*01_INPUTS!S29*(1-01_INPUTS!S23),""),"")
A12: ROCE − WACC (creación de valor) | B12: p.p. | G12: n/a (ver 02_ESTADOS_PROYECTADOS) | H12: n/a (ver 02_ESTADOS_PROYECTADOS) | I12: =IF(01_INPUTS!I17,IFERROR(I10-I11,""),"") -> 0.52662762 | J12: =IF(01_INPUTS!J17,IFERROR(J10-J11,""),"") | K12: =IF(01_INPUTS!K17,IFERROR(K10-K11,""),"") | L12: =IF(01_INPUTS!L17,IFERROR(L10-L11,""),"") | M12: =IF(01_INPUTS!M17,IFERROR(M10-M11,""),"") | N12: =IF(01_INPUTS!N17,IFERROR(N10-N11,""),"") | O12: =IF(01_INPUTS!O17,IFERROR(O10-O11,""),"") | P12: =IF(01_INPUTS!P17,IFERROR(P10-P11,""),"") | ... S12: =IF(01_INPUTS!S17,IFERROR(S10-S11,""),"")
A13: EPS — Beneficio neto / N° acciones | B13: USD/acción | G13: n/a (ver 02_ESTADOS_PROYECTADOS) | H13: n/a (ver 02_ESTADOS_PROYECTADOS) | I13: =IF(01_INPUTS!I17,IFERROR(_ENGINE_FINANCIERO!I168/(_ENGINE_FINANCIERO!I178),""),"") -> 8.3785023 | J13: =IF(01_INPUTS!J17,IFERROR(_ENGINE_FINANCIERO!J168/(_ENGINE_FINANCIERO!J178),""),"") | K13: =IF(01_INPUTS!K17,IFERROR(_ENGINE_FINANCIERO!K168/(_ENGINE_FINANCIERO!K178),""),"") | L13: =IF(01_INPUTS!L17,IFERROR(_ENGINE_FINANCIERO!L168/(_ENGINE_FINANCIERO!L178),""),"") | M13: =IF(01_INPUTS!M17,IFERROR(_ENGINE_FINANCIERO!M168/(_ENGINE_FINANCIERO!M178),""),"") | N13: =IF(01_INPUTS!N17,IFERROR(_ENGINE_FINANCIERO!N168/(_ENGINE_FINANCIERO!N178),""),"") | O13: =IF(01_INPUTS!O17,IFERROR(_ENGINE_FINANCIERO!O168/(_ENGINE_FINANCIERO!O178),""),"") | P13: =IF(01_INPUTS!P17,IFERROR(_ENGINE_FINANCIERO!P168/(_ENGINE_FINANCIERO!P178),""),"") | ... S13: =IF(01_INPUTS!S17,IFERROR(_ENGINE_FINANCIERO!S168/(_ENGINE_FINANCIERO!S178),""),"")
A14: CAJA Y DEUDA
